Workbook

Sheet ANALISE PRODUTO
E1: =TEXT(COUNT(D3:D10000), "#.###") & " SKU" | R1: =TEXT(COUNTIFS(D3:D10000,">0",S3:S10000,"S"), "#.###") & " SKU FL" | U1: =SUBTOTAL(9,U3:U10000) | V1: =SUBTOTAL(9,V3:V10000) | AA1: =SUBTOTAL(9,AA3:AA10000) | AB1: =SUBTOTAL(9,AB3:AB10000) | AC1: =SUBTOTAL(9,AC3:AC10000) | AJ1: =SUBTOTAL(9,AJ3:AJ10000) | AN1: =SUBTOTAL(9,AN3:AN10000) | AO1: =SUBTOTAL(9,AO3:AO10000) | AP1: =SUBTOTAL(9,AP3:AP10000) | AQ1: =SUBTOTAL(9,AQ3:AQ10000) | AR1: =SUBTOTAL(9,AR3:AR10000) | AS1: =SUBTOTAL(9,AS3:AS10000) | AT1: =SUBTOTAL(9,AT3:AT10000) | AU1: =IFERROR((SUBTOTAL(9,AN3:AN10000)/SUBTOTAL(9,AJ3:AJ10000)), 0) | AV1: =IFERROR(((SUBTOTAL(9,AO3:AO10000)) / SUBTOTAL(9,AJ3:AJ10000)), 0) | AX1: =SUBTOTAL(9,AX3:AX10000) | AZ1: {=SUMPRODUCT(SUBTOTAL(9,OFFSET(AZ3,ROW(AZ3:AZ10000)-ROW(AZ3),0,1)),--(AZ3:AZ10000>0))} | BA1: =SUBTOTAL(9,BA3:BA10000) | BB1: =SUBTOTAL(9,BB3:BB10000) | BC1: =SUBTOTAL(9,BC3:BC10000) | BD1: =SUBTOTAL(9,BD3:BD10000) | BE1: =SUBTOTAL(101,BE3:BE10000) | BF1: =SUBTOTAL(101,BF3:BF10000) | BH1: =SUBTOTAL(9,BH3:BH10000) | BI1: =SUBTOTAL(9,BI3:BI10000) | BJ1: =SUBTOTAL(9,BJ3:BJ10000) | BK1: =SUBTOTAL(9,BK3:BK10000) | BL1: =SUBTOTAL(9,BL3:BL10000) | BM1: =SUBTOTAL(101,BM3:BM10000) | BN1: =SUBTOTAL(9,BN3:BN10000) | BO1: =SUBTOTAL(9,BO3:BO10000) | BP1: =SUBTOTAL(9,BP3:BP10000) | BQ1: =SUBTOTAL(9,BQ3:BQ10000) | BR1: =SUBTOTAL(9,BR3:BR5706) | BS1: =SUBTOTAL(9,BS3:BS10000) | BT1: =SUBTOTAL(9,BT3:BT10000) | BU1: =SUBTOTAL(9,BU3:BU10000) | BV1: =SUBTOTAL(9,BV3:BV10000) | BW1: =SUBTOTAL(9,BW3:BW10000) | CB1: =SUBTOTAL(9,CB3:CB10000) | CC1: =SUBTOTAL(9,CC3:CC10000)
A2: Filial | B2: BARRAS | C2: CODIGO PRINCIPAL | D2: Código Produto | E2: DESCRIÇÃO | F2: COD. FORNEC | G2: FORNECEDOR | H2: COMPRADOR | I2: COD COMPRADOR | J2: COD. MARCA | K2: MARCA | L2: COD. DEP. | M2: DEPARTAMENTO | N2: COD. SESSÃO | O2: SESSÃO | P2: COD. LINHA | Q2: LINHA | R2: CURVA ABC | S2: FORA DE LINHA | T2: CLASSE | U2: ESTOQUE DISPONÍVEL | V2: QUANTIDADE PEDIDA PENDENTE | X2: AVARIADO | Y2: BLOQUEADO | Z2: RESERVADO | AA2: QUANTIDADE VENDIDA TRI | AB2: GIRO MÉDIO MENSAL | AC2: GIRO DIA | AD2: DATA ULTIMA ENTRADA | AE2: POSITIVAÇÃO | AF2: PREÇO PEDIDO COMPRA | AG2: CUSTO REAL | AH2: CUSTO REAL SEM ST | AI2: PREÇO MÉDIO VENDA | AJ2: VALOR MEDIA VENDA MÊS | AK2: MÊS P/ RUPTURA | AL2: MÉDIA IDEAL ESTOQUE | AM2: MÊS P/ EXCESSO | AN2: VALOR ESTOQUE PREÇO VENDA | AO2: VALOR ESTOQUE PREÇO VENDA + PENDÊNCIA | AP2: VALOR ESTOQUE PREÇO CUSTO | AQ2: VALOR ESTOQUE PREÇO CUSTO + PENDÊNCIA | AR2: ESTOQUE VALOR A | AS2: ESTOQUE VALOR B | AT2: ESTOQUE VALOR C | AU2: MÊS S/ PENDÊNCIA | AV2: MÊS + PENDÊNCIA | AW2: ESTOQUE IDEAL UND | AX2: ESTOQUE IDEAL CUSTO VALOR | AY2: ESTOQUE LIMITE RUPTURA UND | AZ2: RUPTURA UND | BA2: RUPTURA VALOR | BB2: Ruptura Valor A | BC2: Ruptura Valor B | BD2: Ruptura Valor C | BE2: NIVEL SERVIÇO RUPTURA S/ PENDÊNCIA | BF2: NIVEL SERVIÇO RUPTURA C/ PENDÊNCIA | BG2: ESTOQUE LIMITE P/ EXCESSO | BH2: EXCESSO UND | BI2: EXCESSO VALOR | BJ2: EXCESSO VALOR A | BK2: EXCESSO VALOR B | BL2: EXCESSO VALOR C | BM2: NÍVEL DE EXCESSO | BN2: VENDA MÉDIA MÊS (CUSTO) | BO2: ESTOQUE ATUAL + DEMANDA (CUSTO) | BP2: ESTOQUE IDEAL (CUSTO) | BQ2: COMPRA MÊS ATUAL (CUSTO) | BR2: COMPRA PRÓXIMO MÊS (CUSTO) | BS2: VENDA MÉDIA MÊS (VENDA) | BT2: ESTOQUE ATUAL + DEMANDA (VENDA) | BU2: ESTOQUE IDEAL (VENDA) | BV2: COMPRA MÊS ATUAL (VENDA) | BW2: COMPRA PRÓXIMO MÊS (VENDA) | BX2: DATA ÚLTIMO PEDIDO | BY2: DATA CADASTRO PRODUTO | BZ2: COMISSÃO INTERNA | CA2: COMISSÃO EXTERNA | CB2: PEDIDO PENDENTE A PREÇO COMPRA | CC2: PEDIDO PENDENTE A PREÇO VENDA | CD2: PREÇO TABELA
A3: =IF(D3="","",VLOOKUP(D3,'produto-estoque-total-7'!A:AB,3,0)) | B3: =IF(D3="","",VLOOKUP(D3,'produto-estoque-total-7'!A:AB,12,0)) | C3: =IF(D3="","",VLOOKUP(D3,'produto-estoque-total-7'!A:AB,2,0)) | D3: =IFERROR(IF('produto-estoque-total-7'!A2="","",'produto-estoque-total-7'!A2),"") | E3: =IF(D3="","",VLOOKUP(D3,'produto-estoque-total-7'!A:AB,4,0)) | F3: =IF(D3="","",VLOOKUP(D3,'produto-estoque-total-7'!A:AB,13,0)) | G3: =IF(F3="","",VLOOKUP(F3,'FORNECEDORES X COMPRADOR'!A:D,4,0)) | H3: =IF(F3="","",VLOOKUP(F3,'FORNECEDORES X COMPRADOR'!A:E,5,0)) | I3: =IF(D3="","",VLOOKUP(D3,'produto-estoque-total-7'!A:AB,15,0)) | J3: =IF(D3="","",VLOOKUP(D3,'produto-estoque-total-7'!A:AB,19,0)) | K3: =IF(D3="","",VLOOKUP(D3,'produto-estoque-total-7'!A:AB,20,0)) | L3: =IF(D3="","",VLOOKUP(D3,'produto-estoque-total-7'!A:AB,17,0)) | M3: =IF(D3="","",VLOOKUP(D3,'produto-estoque-total-7'!A:AB,18,0)) | N3: =IF(D3="","",VLOOKUP(D3,'produto-estoque-total-7'!A:AB,21,0)) | O3: =IF(D3="","",VLOOKUP(D3,'produto-estoque-total-7'!A:AB,22,0)) | P3: =IF(D3="","",VLOOKUP(D3,'produto-estoque-total-7'!A:AB,23,0)) | Q3: =IF(D3="","",VLOOKUP(D3,'produto-estoque-total-7'!A:AB,24,0)) | R3: =IFERROR(IF(D3="","",VLOOKUP(D3,'produto-venda-7'!B:N,13,0)),"C") | S3: =IF(D3="","",VLOOKUP(D3,'produto-estoque-total-7'!A:AB,6,0)) | T3: =IF(D3="","",VLOOKUP(D3,'produto-estoque-total-7'!A:AB,5,0)) | U3: =IF(D3="","",VLOOKUP(D3,'produto-estoque-total-7'!A:AB,11,0)) | V3: =IF(D3="","",IFERROR(VLOOKUP(D3,'produto-entrada-7'!A:M,10,0),0)) | X3: =IF(D3="","",VLOOKUP(D3,'produto-estoque-total-7'!A:AB,8,0)) | Y3: =IF(D3="","",VLOOKUP(D3,'produto-estoque-total-7'!A:AB,9,0)) | Z3: =IF(D3="","",VLOOKUP(D3,'produto-estoque-total-7'!A:AB,10,0)) | AA3: =IFERROR(IF(D3="","",VLOOKUP(D3,'produto-venda-7'!B:N,4,0)),0) | AB3: =IFERROR(IF(D3="","",VLOOKUP(D3,'produto-venda-7'!B:N,5,0)),0) | AC3: =IF(D3="","",IFERROR(AA3/90,0)) | AD3: =IF(D3="","",IFERROR(VLOOKUP(D3,'produto-entrada-7'!A:M,4,0),0)) | AE3: =IFERROR(IF(D3="","",VLOOKUP(D3,'produto-venda-7'!B:N,10,0)),0) | AF3: =IF(D3="","",IFERROR(VLOOKUP(D3,'produto-entrada-7'!A:M,11,0),0)) | AG3: =IF(D3="","",IFERROR(VLOOKUP(D3,'produto-entrada-7'!A:M,12,0),0)) | AH3: =IF(D3="","",IFERROR(VLOOKUP(D3,'produto-entrada-7'!A:M,13,0),0)) | AI3: =IFERROR(IF(D3="","",VLOOKUP(D3,'produto-venda-7'!B:N,11,0)),0) | AJ3: =IF(D3="","",IFERROR(AI3*AB3,0)) | AK3: =IFERROR(IF(D3="","",VLOOKUP(F3,'ANALISE FORNECEDOR'!$A:$I,8,0)),"") | AL3: =IF(D3="","",AVERAGE(AM3,AK3)) | AM3: =IFERROR(IF(D3="","",VLOOKUP(F3,'ANALISE FORNECEDOR'!$A:$I,9,0)),"") | AN3: =IF(D3="","",IF(Y3>12,AI3*(U3+Y3),AI3*U3)) | AO3: =IF(D3="","",IF(Y3>12,AI3*(U3+V3+Y3),AI3*(U3+V3))) | AP3: =IF(D3="","",IF(Y3>12,AG3*(U3+Y3),AG3*U3)) | AQ3: =IF(D3="","",IF(Y3>12,AG3*(U3+V3+Y3),AG3*(U3+V3))) | AR3: =IF(D3="","",IF(OR(R3="A",R3="AA",R3="AAA"),AP3,0)) | AS3: =IF(D3="","",IF(R3="B",AP3,0)) | AT3: =IF(D3="","",IF(R3="C",AP3,0)) | AU3: =IF(D3="","",IFERROR(AN3/AJ3,0)) | AV3: =IF(D3="","",IFERROR(((AO3)/AJ3),0)) | AW3: =IF(D3="","",IF(OR(S3="S",NOT(AND(ISNUMBER(AC3),ISNUMBER(AL3),AC3*AL3>=0))),0,AC3*AL3)) | AX3: =IFERROR(IF(D3="","",AW3*AG3),0) | AY3: =IF(D3="","",IF(OR(S3="S",NOT(AND(ISNUMBER(AC3),ISNUMBER(AK3),AC3*AK3>=0))),0,AC3*AK3)) | AZ3: =IFERROR(IF(D3="","",IF(AY3=0,0,IF(((AY3)-(U3+Y3))<0,0,(AY3)-U3))),0) | BA3: =IF(D3="","",AZ3*AG3) | BB3: =IF(D3="","",IF(OR(R3="A",R3="AA",R3="AAA"),BA3,0)) | BC3: =IF(D3="","",IF(R3="B",BA3,0)) | BD3: =IF(D3="","",IF(R3="B",BA3,0)) | BE3: =IF(D3="","",IF(S3="S", 1, IF(AC3=0, 1, IF( IFERROR(((U3+Y3)*AG3)/((AC3*AK3)*AG3),0)<0, 0, IF( IFERROR(((U3+Y3)*AG3)/((AC3*AK3)*AG3),0)>1, 1, IFERROR(((U3+Y3)*AG3)/((AC3*AK3)*AG3),0) ) ) ) )) | BF3: =IF(D3="","",IF(S3="S", 1, IF(AC3=0, 1, IF( IFERROR(((U3+V3+Y3)*AG3)/((AC3*AK3)*AG3),0)<0, 0, IF( IFERROR(((U3+V3+Y3)*AG3)/((AC3*AK3)*AG3),0)>1, 1, IFERROR(((U3+V3+Y3)*AG3)/((AC3*AK3)*AG3),0) ) ) ) )) | BG3: =IF(D3="","",IF(S3="S",0,IF(AND(ISNUMBER(AC3),ISNUMBER(AM3)),IF(OR(AC3*AM3<0,ISERR(AC3*AM3)),0,AC3*AM3),0))) | BH3: =IF(D3="","",IF(BY3>TODAY()-60,0,IF(Y3>12,MAX(0,(U3+Y3)-BG3),MAX(0,U3-BG3)))) | BI3: =IF(D3="","",BH3*AG3) | BJ3: =IF(D3="","",IF(OR(R3="A",R3="AA",R3="AAA"),BI3,0)) | BK3: =IF(D3="","",IF(R3="B",BI3,0)) | BL3: =IF(D3="","",IF(R3="C",BI3,0)) | BM3: =IF(D3="","",IFERROR(MAX(0,MIN(BI3/AP3,1)),0)) | BN3: =IF(D3="","",AB3*AG3) | BO3: =IF(D3="","",(U3+V3+X3)*AG3) | BP3: =IF(D3="","",(AB3*3)*AG3) | BQ3: =IF(D3="","",IF(BO3-BP3>0,0,BO3-BP3)) | BR3: =IF(D3="","",IF(BO3-BP3-BN3>0,0,BO3-BP3-BN3)) | BS3: =IF(D3="","",IFERROR(AB3*AI3,0)) | BT3: =IF(D3="","",IFERROR(IF(X3>12, AI3*(U3+V3+X3), AI3*(U3+V3)),0)) | BU3: =IF(D3="","",IFERROR(((AB3*3)*AI3),0)) | BV3: =IF(D3="","",IF(BT3-BU3>0,0,BT3-BU3)) | BW3: =IF(D3="","",IF(BT3-BU3-BS3>0,0,BT3-BU3-BS3)) | BX3: =IF(D3="","",IFERROR(VLOOKUP(D3,'produto-entrada-7'!A:M,3,0),"SEM PEDIDO")) | BY3: =IF(D3="","",VLOOKUP(D3,'produto-estoque-total-7'!A:AB,25,0)) | BZ3: =IF(D3="","",IFERROR(VLOOKUP(D3,'produto-estoque-total-7'!A:AB,26,0)/100,0)) | CA3: =IF(D3="","",IFERROR(VLOOKUP(D3,'produto-estoque-total-7'!A:AB,27,0)/100,0)) | CB3: =IF(D3="","",V3*AF3) | CC3: =IF(D3="","",V3*AI3) | CD3: =IF(D3="","",VLOOKUP(D3,'produto-estoque-total-7'!A:AB,28,0))
A4: =IF(D4="","",VLOOKUP(D4,'produto-estoque-total-7'!A:AB,3,0)) | B4: =IF(D4="","",VLOOKUP(D4,'produto-estoque-total-7'!A:AB,12,0)) | C4: =IF(D4="","",VLOOKUP(D4,'produto-estoque-total-7'!A:AB,2,0)) | D4: =IFERROR(IF('produto-estoque-total-7'!A3="","",'produto-estoque-total-7'!A3),"") | E4: =IF(D4="","",VLOOKUP(D4,'produto-estoque-total-7'!A:AB,4,0)) | F4: =IF(D4="","",VLOOKUP(D4,'produto-estoque-total-7'!A:AB,13,0)) | G4: =IF(F4="","",VLOOKUP(F4,'FORNECEDORES X COMPRADOR'!A:D,4,0)) | H4: =IF(F4="","",VLOOKUP(F4,'FORNECEDORES X COMPRADOR'!A:E,5,0)) | I4: =IF(D4="","",VLOOKUP(D4,'produto-estoque-total-7'!A:AB,15,0)) | J4: =IF(D4="","",VLOOKUP(D4,'produto-estoque-total-7'!A:AB,19,0)) | K4: =IF(D4="","",VLOOKUP(D4,'produto-estoque-total-7'!A:AB,20,0)) | L4: =IF(D4="","",VLOOKUP(D4,'produto-estoque-total-7'!A:AB,17,0)) | M4: =IF(D4="","",VLOOKUP(D4,'produto-estoque-total-7'!A:AB,18,0)) | N4: =IF(D4="","",VLOOKUP(D4,'produto-estoque-total-7'!A:AB,21,0)) | O4: =IF(D4="","",VLOOKUP(D4,'produto-estoque-total-7'!A:AB,22,0)) | P4: =IF(D4="","",VLOOKUP(D4,'produto-estoque-total-7'!A:AB,23,0)) | Q4: =IF(D4="","",VLOOKUP(D4,'produto-estoque-total-7'!A:AB,24,0)) | R4: =IFERROR(IF(D4="","",VLOOKUP(D4,'produto-venda-7'!B:N,13,0)),"C") | S4: =IF(D4="","",VLOOKUP(D4,'produto-estoque-total-7'!A:AB,6,0)) | T4: =IF(D4="","",VLOOKUP(D4,'produto-estoque-total-7'!A:AB,5,0)) | U4: =IF(D4="","",VLOOKUP(D4,'produto-estoque-total-7'!A:AB,11,0)) | V4: =IF(D4="","",IFERROR(VLOOKUP(D4,'produto-entrada-7'!A:M,10,0),0)) | X4: =IF(D4="","",VLOOKUP(D4,'produto-estoque-total-7'!A:AB,8,0)) | Y4: =IF(D4="","",VLOOKUP(D4,'produto-estoque-total-7'!A:AB,9,0)) | Z4: =IF(D4="","",VLOOKUP(D4,'produto-estoque-total-7'!A:AB,10,0)) | AA4: =IFERROR(IF(D4="","",VLOOKUP(D4,'produto-venda-7'!B:N,4,0)),0) | AB4: =IFERROR(IF(D4="","",VLOOKUP(D4,'produto-venda-7'!B:N,5,0)),0) | AC4: =IF(D4="","",IFERROR(AA4/90,0)) | AD4: =IF(D4="","",IFERROR(VLOOKUP(D4,'produto-entrada-7'!A:M,4,0),0)) | AE4: =IFERROR(IF(D4="","",VLOOKUP(D4,'produto-venda-7'!B:N,10,0)),0) | AF4: =IF(D4="","",IFERROR(VLOOKUP(D4,'produto-entrada-7'!A:M,11,0),0)) | AG4: =IF(D4="","",IFERROR(VLOOKUP(D4,'produto-entrada-7'!A:M,12,0),0)) | AH4: =IF(D4="","",IFERROR(VLOOKUP(D4,'produto-entrada-7'!A:M,13,0),0)) | AI4: =IFERROR(IF(D4="","",VLOOKUP(D4,'produto-venda-7'!B:N,11,0)),0) | AJ4: =IF(D4="","",IFERROR(AI4*AB4,0)) | AK4: =IFERROR(IF(D4="","",VLOOKUP(F4,'ANALISE FORNECEDOR'!$A:$I,8,0)),"") | AL4: =IF(D4="","",AVERAGE(AM4,AK4)) | AM4: =IFERROR(IF(D4="","",VLOOKUP(F4,'ANALISE FORNECEDOR'!$A:$I,9,0)),"") | AN4: =IF(D4="","",IF(Y4>12,AI4*(U4+Y4),AI4*U4)) | AO4: =IF(D4="","",IF(Y4>12,AI4*(U4+V4+Y4),AI4*(U4+V4))) | AP4: =IF(D4="","",IF(Y4>12,AG4*(U4+Y4),AG4*U4)) | AQ4: =IF(D4="","",IF(Y4>12,AG4*(U4+V4+Y4),AG4*(U4+V4))) | AR4: =IF(D4="","",IF(OR(R4="A",R4="AA",R4="AAA"),AP4,0)) | AS4: =IF(D4="","",IF(R4="B",AP4,0)) | AT4: =IF(D4="","",IF(R4="C",AP4,0)) | AU4: =IF(D4="","",IFERROR(AN4/AJ4,0)) | AV4: =IF(D4="","",IFERROR(((AO4)/AJ4),0)) | AW4: =IF(D4="","",IF(OR(S4="S",NOT(AND(ISNUMBER(AC4),ISNUMBER(AL4),AC4*AL4>=0))),0,AC4*AL4)) | AX4: =IFERROR(IF(D4="","",AW4*AG4),0) | AY4: =IF(D4="","",IF(OR(S4="S",NOT(AND(ISNUMBER(AC4),ISNUMBER(AK4),AC4*AK4>=0))),0,AC4*AK4)) | AZ4: =IFERROR(IF(D4="","",IF(AY4=0,0,IF(((AY4)-(U4+Y4))<0,0,(AY4)-U4))),0) | BA4: =IF(D4="","",AZ4*AG4) | BB4: =IF(D4="","",IF(OR(R4="A",R4="AA",R4="AAA"),BA4,0)) | BC4: =IF(D4="","",IF(R4="B",BA4,0)) | BD4: =IF(D4="","",IF(R4="B",BA4,0)) | BE4: =IF(D4="","",IF(S4="S", 1, IF(AC4=0, 1, IF( IFERROR(((U4+Y4)*AG4)/((AC4*AK4)*AG4),0)<0, 0, IF( IFERROR(((U4+Y4)*AG4)/((AC4*AK4)*AG4),0)>1, 1, IFERROR(((U4+Y4)*AG4)/((AC4*AK4)*AG4),0) ) ) ) )) | BF4: =IF(D4="","",IF(S4="S", 1, IF(AC4=0, 1, IF( IFERROR(((U4+V4+Y4)*AG4)/((AC4*AK4)*AG4),0)<0, 0, IF( IFERROR(((U4+V4+Y4)*AG4)/((AC4*AK4)*AG4),0)>1, 1, IFERROR(((U4+V4+Y4)*AG4)/((AC4*AK4)*AG4),0) ) ) ) )) | BG4: =IF(D4="","",IF(S4="S",0,IF(AND(ISNUMBER(AC4),ISNUMBER(AM4)),IF(OR(AC4*AM4<0,ISERR(AC4*AM4)),0,AC4*AM4),0))) | BH4: =IF(D4="","",IF(BY4>TODAY()-60,0,IF(Y4>12,MAX(0,(U4+Y4)-BG4),MAX(0,U4-BG4)))) | BI4: =IF(D4="","",BH4*AG4) | BJ4: =IF(D4="","",IF(OR(R4="A",R4="AA",R4="AAA"),BI4,0)) | BK4: =IF(D4="","",IF(R4="B",BI4,0)) | BL4: =IF(D4="","",IF(R4="C",BI4,0)) | BM4: =IF(D4="","",IFERROR(MAX(0,MIN(BI4/AP4,1)),0)) | BN4: =IF(D4="","",AB4*AG4) | BO4: =IF(D4="","",(U4+V4+X4)*AG4) | BP4: =IF(D4="","",(AB4*3)*AG4) | BQ4: =IF(D4="","",IF(BO4-BP4>0,0,BO4-BP4)) | BR4: =IF(D4="","",IF(BO4-BP4-BN4>0,0,BO4-BP4-BN4)) | BS4: =IF(D4="","",IFERROR(AB4*AI4,0)) | BT4: =IF(D4="","",IFERROR(IF(X4>12, AI4*(U4+V4+X4), AI4*(U4+V4)),0)) | BU4: =IF(D4="","",IFERROR(((AB4*3)*AI4),0)) | BV4: =IF(D4="","",IF(BT4-BU4>0,0,BT4-BU4)) | BW4: =IF(D4="","",IF(BT4-BU4-BS4>0,0,BT4-BU4-BS4)) | BX4: =IF(D4="","",IFERROR(VLOOKUP(D4,'produto-entrada-7'!A:M,3,0),"SEM PEDIDO")) | BY4: =IF(D4="","",VLOOKUP(D4,'produto-estoque-total-7'!A:AB,25,0)) | BZ4: =IF(D4="","",IFERROR(VLOOKUP(D4,'produto-estoque-total-7'!A:AB,26,0)/100,0)) | CA4: =IF(D4="","",IFERROR(VLOOKUP(D4,'produto-estoque-total-7'!A:AB,27,0)/100,0)) | CB4: =IF(D4="","",V4*AF4) | CC4: =IF(D4="","",V4*AI4) | CD4: =IF(D4="","",VLOOKUP(D4,'produto-estoque-total-7'!A:AB,28,0))
A5: =IF(D5="","",VLOOKUP(D5,'produto-estoque-total-7'!A:AB,3,0)) | B5: =IF(D5="","",VLOOKUP(D5,'produto-estoque-total-7'!A:AB,12,0)) | C5: =IF(D5="","",VLOOKUP(D5,'produto-estoque-total-7'!A:AB,2,0)) | D5: =IFERROR(IF('produto-estoque-total-7'!A4="","",'produto-estoque-total-7'!A4),"") | E5: =IF(D5="","",VLOOKUP(D5,'produto-estoque-total-7'!A:AB,4,0)) | F5: =IF(D5="","",VLOOKUP(D5,'produto-estoque-total-7'!A:AB,13,0)) | G5: =IF(F5="","",VLOOKUP(F5,'FORNECEDORES X COMPRADOR'!A:D,4,0)) | H5: =IF(F5="","",VLOOKUP(F5,'FORNECEDORES X COMPRADOR'!A:E,5,0)) | I5: =IF(D5="","",VLOOKUP(D5,'produto-estoque-total-7'!A:AB,15,0)) | J5: =IF(D5="","",VLOOKUP(D5,'produto-estoque-total-7'!A:AB,19,0)) | K5: =IF(D5="","",VLOOKUP(D5,'produto-estoque-total-7'!A:AB,20,0)) | L5: =IF(D5="","",VLOOKUP(D5,'produto-estoque-total-7'!A:AB,17,0)) | M5: =IF(D5="","",VLOOKUP(D5,'produto-estoque-total-7'!A:AB,18,0)) | N5: =IF(D5="","",VLOOKUP(D5,'produto-estoque-total-7'!A:AB,21,0)) | O5: =IF(D5="","",VLOOKUP(D5,'produto-estoque-total-7'!A:AB,22,0)) | P5: =IF(D5="","",VLOOKUP(D5,'produto-estoque-total-7'!A:AB,23,0)) | Q5: =IF(D5="","",VLOOKUP(D5,'produto-estoque-total-7'!A:AB,24,0)) | R5: =IFERROR(IF(D5="","",VLOOKUP(D5,'produto-venda-7'!B:N,13,0)),"C") | S5: =IF(D5="","",VLOOKUP(D5,'produto-estoque-total-7'!A:AB,6,0)) | T5: =IF(D5="","",VLOOKUP(D5,'produto-estoque-total-7'!A:AB,5,0)) | U5: =IF(D5="","",VLOOKUP(D5,'produto-estoque-total-7'!A:AB,11,0)) | V5: =IF(D5="","",IFERROR(VLOOKUP(D5,'produto-entrada-7'!A:M,10,0),0)) | X5: =IF(D5="","",VLOOKUP(D5,'produto-estoque-total-7'!A:AB,8,0)) | Y5: =IF(D5="","",VLOOKUP(D5,'produto-estoque-total-7'!A:AB,9,0)) | Z5: =IF(D5="","",VLOOKUP(D5,'produto-estoque-total-7'!A:AB,10,0)) | AA5: =IFERROR(IF(D5="","",VLOOKUP(D5,'produto-venda-7'!B:N,4,0)),0) | AB5: =IFERROR(IF(D5="","",VLOOKUP(D5,'produto-venda-7'!B:N,5,0)),0) | AC5: =IF(D5="","",IFERROR(AA5/90,0)) | AD5: =IF(D5="","",IFERROR(VLOOKUP(D5,'produto-entrada-7'!A:M,4,0),0)) | AE5: =IFERROR(IF(D5="","",VLOOKUP(D5,'produto-venda-7'!B:N,10,0)),0) | AF5: =IF(D5="","",IFERROR(VLOOKUP(D5,'produto-entrada-7'!A:M,11,0),0)) | AG5: =IF(D5="","",IFERROR(VLOOKUP(D5,'produto-entrada-7'!A:M,12,0),0)) | AH5: =IF(D5="","",IFERROR(VLOOKUP(D5,'produto-entrada-7'!A:M,13,0),0)) | AI5: =IFERROR(IF(D5="","",VLOOKUP(D5,'produto-venda-7'!B:N,11,0)),0) | AJ5: =IF(D5="","",IFERROR(AI5*AB5,0)) | AK5: =IFERROR(IF(D5="","",VLOOKUP(F5,'ANALISE FORNECEDOR'!$A:$I,8,0)),"") | AL5: =IF(D5="","",AVERAGE(AM5,AK5)) | AM5: =IFERROR(IF(D5="","",VLOOKUP(F5,'ANALISE FORNECEDOR'!$A:$I,9,0)),"") | AN5: =IF(D5="","",IF(Y5>12,AI5*(U5+Y5),AI5*U5)) | AO5: =IF(D5="","",IF(Y5>12,AI5*(U5+V5+Y5),AI5*(U5+V5))) | AP5: =IF(D5="","",IF(Y5>12,AG5*(U5+Y5),AG5*U5)) | AQ5: =IF(D5="","",IF(Y5>12,AG5*(U5+V5+Y5),AG5*(U5+V5))) | AR5: =IF(D5="","",IF(OR(R5="A",R5="AA",R5="AAA"),AP5,0)) | AS5: =IF(D5="","",IF(R5="B",AP5,0)) | AT5: =IF(D5="","",IF(R5="C",AP5,0)) | AU5: =IF(D5="","",IFERROR(AN5/AJ5,0)) | AV5: =IF(D5="","",IFERROR(((AO5)/AJ5),0)) | AW5: =IF(D5="","",IF(OR(S5="S",NOT(AND(ISNUMBER(AC5),ISNUMBER(AL5),AC5*AL5>=0))),0,AC5*AL5)) | AX5: =IFERROR(IF(D5="","",AW5*AG5),0) | AY5: =IF(D5="","",IF(OR(S5="S",NOT(AND(ISNUMBER(AC5),ISNUMBER(AK5),AC5*AK5>=0))),0,AC5*AK5)) | AZ5: =IFERROR(IF(D5="","",IF(AY5=0,0,IF(((AY5)-(U5+Y5))<0,0,(AY5)-U5))),0) | BA5: =IF(D5="","",AZ5*AG5) | BB5: =IF(D5="","",IF(OR(R5="A",R5="AA",R5="AAA"),BA5,0)) | BC5: =IF(D5="","",IF(R5="B",BA5,0)) | BD5: =IF(D5="","",IF(R5="B",BA5,0)) | BE5: =IF(D5="","",IF(S5="S", 1, IF(AC5=0, 1, IF( IFERROR(((U5+Y5)*AG5)/((AC5*AK5)*AG5),0)<0, 0, IF( IFERROR(((U5+Y5)*AG5)/((AC5*AK5)*AG5),0)>1, 1, IFERROR(((U5+Y5)*AG5)/((AC5*AK5)*AG5),0) ) ) ) )) | BF5: =IF(D5="","",IF(S5="S", 1, IF(AC5=0, 1, IF( IFERROR(((U5+V5+Y5)*AG5)/((AC5*AK5)*AG5),0)<0, 0, IF( IFERROR(((U5+V5+Y5)*AG5)/((AC5*AK5)*AG5),0)>1, 1, IFERROR(((U5+V5+Y5)*AG5)/((AC5*AK5)*AG5),0) ) ) ) )) | BG5: =IF(D5="","",IF(S5="S",0,IF(AND(ISNUMBER(AC5),ISNUMBER(AM5)),IF(OR(AC5*AM5<0,ISERR(AC5*AM5)),0,AC5*AM5),0))) | BH5: =IF(D5="","",IF(BY5>TODAY()-60,0,IF(Y5>12,MAX(0,(U5+Y5)-BG5),MAX(0,U5-BG5)))) | BI5: =IF(D5="","",BH5*AG5) | BJ5: =IF(D5="","",IF(OR(R5="A",R5="AA",R5="AAA"),BI5,0)) | BK5: =IF(D5="","",IF(R5="B",BI5,0)) | BL5: =IF(D5="","",IF(R5="C",BI5,0)) | BM5: =IF(D5="","",IFERROR(MAX(0,MIN(BI5/AP5,1)),0)) | BN5: =IF(D5="","",AB5*AG5) | BO5: =IF(D5="","",(U5+V5+X5)*AG5) | BP5: =IF(D5="","",(AB5*3)*AG5) | BQ5: =IF(D5="","",IF(BO5-BP5>0,0,BO5-BP5)) | BR5: =IF(D5="","",IF(BO5-BP5-BN5>0,0,BO5-BP5-BN5)) | BS5: =IF(D5="","",IFERROR(AB5*AI5,0)) | BT5: =IF(D5="","",IFERROR(IF(X5>12, AI5*(U5+V5+X5), AI5*(U5+V5)),0)) | BU5: =IF(D5="","",IFERROR(((AB5*3)*AI5),0)) | BV5: =IF(D5="","",IF(BT5-BU5>0,0,BT5-BU5)) | BW5: =IF(D5="","",IF(BT5-BU5-BS5>0,0,BT5-BU5-BS5)) | BX5: =IF(D5="","",IFERROR(VLOOKUP(D5,'produto-entrada-7'!A:M,3,0),"SEM PEDIDO")) | BY5: =IF(D5="","",VLOOKUP(D5,'produto-estoque-total-7'!A:AB,25,0)) | BZ5: =IF(D5="","",IFERROR(VLOOKUP(D5,'produto-estoque-total-7'!A:AB,26,0)/100,0)) | CA5: =IF(D5="","",IFERROR(VLOOKUP(D5,'produto-estoque-total-7'!A:AB,27,0)/100,0)) | CB5: =IF(D5="","",V5*AF5) | CC5: =IF(D5="","",V5*AI5) | CD5: =IF(D5="","",VLOOKUP(D5,'produto-estoque-total-7'!A:AB,28,0))
A6: =IF(D6="","",VLOOKUP(D6,'produto-estoque-total-7'!A:AB,3,0)) | B6: =IF(D6="","",VLOOKUP(D6,'produto-estoque-total-7'!A:AB,12,0)) | C6: =IF(D6="","",VLOOKUP(D6,'produto-estoque-total-7'!A:AB,2,0)) | D6: =IFERROR(IF('produto-estoque-total-7'!A5="","",'produto-estoque-total-7'!A5),"") | E6: =IF(D6="","",VLOOKUP(D6,'produto-estoque-total-7'!A:AB,4,0)) | F6: =IF(D6="","",VLOOKUP(D6,'produto-estoque-total-7'!A:AB,13,0)) | G6: =IF(F6="","",VLOOKUP(F6,'FORNECEDORES X COMPRADOR'!A:D,4,0)) | H6: =IF(F6="","",VLOOKUP(F6,'FORNECEDORES X COMPRADOR'!A:E,5,0)) | I6: =IF(D6="","",VLOOKUP(D6,'produto-estoque-total-7'!A:AB,15,0)) | J6: =IF(D6="","",VLOOKUP(D6,'produto-estoque-total-7'!A:AB,19,0)) | K6: =IF(D6="","",VLOOKUP(D6,'produto-estoque-total-7'!A:AB,20,0)) | L6: =IF(D6="","",VLOOKUP(D6,'produto-estoque-total-7'!A:AB,17,0)) | M6: =IF(D6="","",VLOOKUP(D6,'produto-estoque-total-7'!A:AB,18,0)) | N6: =IF(D6="","",VLOOKUP(D6,'produto-estoque-total-7'!A:AB,21,0)) | O6: =IF(D6="","",VLOOKUP(D6,'produto-estoque-total-7'!A:AB,22,0)) | P6: =IF(D6="","",VLOOKUP(D6,'produto-estoque-total-7'!A:AB,23,0)) | Q6: =IF(D6="","",VLOOKUP(D6,'produto-estoque-total-7'!A:AB,24,0)) | R6: =IFERROR(IF(D6="","",VLOOKUP(D6,'produto-venda-7'!B:N,13,0)),"C") | S6: =IF(D6="","",VLOOKUP(D6,'produto-estoque-total-7'!A:AB,6,0)) | T6: =IF(D6="","",VLOOKUP(D6,'produto-estoque-total-7'!A:AB,5,0)) | U6: =IF(D6="","",VLOOKUP(D6,'produto-estoque-total-7'!A:AB,11,0)) | V6: =IF(D6="","",IFERROR(VLOOKUP(D6,'produto-entrada-7'!A:M,10,0),0)) | X6: =IF(D6="","",VLOOKUP(D6,'produto-estoque-total-7'!A:AB,8,0)) | Y6: =IF(D6="","",VLOOKUP(D6,'produto-estoque-total-7'!A:AB,9,0)) | Z6: =IF(D6="","",VLOOKUP(D6,'produto-estoque-total-7'!A:AB,10,0)) | AA6: =IFERROR(IF(D6="","",VLOOKUP(D6,'produto-venda-7'!B:N,4,0)),0) | AB6: =IFERROR(IF(D6="","",VLOOKUP(D6,'produto-venda-7'!B:N,5,0)),0) | AC6: =IF(D6="","",IFERROR(AA6/90,0)) | AD6: =IF(D6="","",IFERROR(VLOOKUP(D6,'produto-entrada-7'!A:M,4,0),0)) | AE6: =IFERROR(IF(D6="","",VLOOKUP(D6,'produto-venda-7'!B:N,10,0)),0) | AF6: =IF(D6="","",IFERROR(VLOOKUP(D6,'produto-entrada-7'!A:M,11,0),0)) | AG6: =IF(D6="","",IFERROR(VLOOKUP(D6,'produto-entrada-7'!A:M,12,0),0)) | AH6: =IF(D6="","",IFERROR(VLOOKUP(D6,'produto-entrada-7'!A:M,13,0),0)) | AI6: =IFERROR(IF(D6="","",VLOOKUP(D6,'produto-venda-7'!B:N,11,0)),0) | AJ6: =IF(D6="","",IFERROR(AI6*AB6,0)) | AK6: =IFERROR(IF(D6="","",VLOOKUP(F6,'ANALISE FORNECEDOR'!$A:$I,8,0)),"") | AL6: =IF(D6="","",AVERAGE(AM6,AK6)) | AM6: =IFERROR(IF(D6="","",VLOOKUP(F6,'ANALISE FORNECEDOR'!$A:$I,9,0)),"") | AN6: =IF(D6="","",IF(Y6>12,AI6*(U6+Y6),AI6*U6)) | AO6: =IF(D6="","",IF(Y6>12,AI6*(U6+V6+Y6),AI6*(U6+V6))) | AP6: =IF(D6="","",IF(Y6>12,AG6*(U6+Y6),AG6*U6)) | AQ6: =IF(D6="","",IF(Y6>12,AG6*(U6+V6+Y6),AG6*(U6+V6))) | AR6: =IF(D6="","",IF(OR(R6="A",R6="AA",R6="AAA"),AP6,0)) | AS6: =IF(D6="","",IF(R6="B",AP6,0)) | AT6: =IF(D6="","",IF(R6="C",AP6,0)) | AU6: =IF(D6="","",IFERROR(AN6/AJ6,0)) | AV6: =IF(D6="","",IFERROR(((AO6)/AJ6),0)) | AW6: =IF(D6="","",IF(OR(S6="S",NOT(AND(ISNUMBER(AC6),ISNUMBER(AL6),AC6*AL6>=0))),0,AC6*AL6)) | AX6: =IFERROR(IF(D6="","",AW6*AG6),0) | AY6: =IF(D6="","",IF(OR(S6="S",NOT(AND(ISNUMBER(AC6),ISNUMBER(AK6),AC6*AK6>=0))),0,AC6*AK6)) | AZ6: =IFERROR(IF(D6="","",IF(AY6=0,0,IF(((AY6)-(U6+Y6))<0,0,(AY6)-U6))),0) | BA6: =IF(D6="","",AZ6*AG6) | BB6: =IF(D6="","",IF(OR(R6="A",R6="AA",R6="AAA"),BA6,0)) | BC6: =IF(D6="","",IF(R6="B",BA6,0)) | BD6: =IF(D6="","",IF(R6="B",BA6,0)) | BE6: =IF(D6="","",IF(S6="S", 1, IF(AC6=0, 1, IF( IFERROR(((U6+Y6)*AG6)/((AC6*AK6)*AG6),0)<0, 0, IF( IFERROR(((U6+Y6)*AG6)/((AC6*AK6)*AG6),0)>1, 1, IFERROR(((U6+Y6)*AG6)/((AC6*AK6)*AG6),0) ) ) ) )) | BF6: =IF(D6="","",IF(S6="S", 1, IF(AC6=0, 1, IF( IFERROR(((U6+V6+Y6)*AG6)/((AC6*AK6)*AG6),0)<0, 0, IF( IFERROR(((U6+V6+Y6)*AG6)/((AC6*AK6)*AG6),0)>1, 1, IFERROR(((U6+V6+Y6)*AG6)/((AC6*AK6)*AG6),0) ) ) ) )) | BG6: =IF(D6="","",IF(S6="S",0,IF(AND(ISNUMBER(AC6),ISNUMBER(AM6)),IF(OR(AC6*AM6<0,ISERR(AC6*AM6)),0,AC6*AM6),0))) | BH6: =IF(D6="","",IF(BY6>TODAY()-60,0,IF(Y6>12,MAX(0,(U6+Y6)-BG6),MAX(0,U6-BG6)))) | BI6: =IF(D6="","",BH6*AG6) | BJ6: =IF(D6="","",IF(OR(R6="A",R6="AA",R6="AAA"),BI6,0)) | BK6: =IF(D6="","",IF(R6="B",BI6,0)) | BL6: =IF(D6="","",IF(R6="C",BI6,0)) | BM6: =IF(D6="","",IFERROR(MAX(0,MIN(BI6/AP6,1)),0)) | BN6: =IF(D6="","",AB6*AG6) | BO6: =IF(D6="","",(U6+V6+X6)*AG6) | BP6: =IF(D6="","",(AB6*3)*AG6) | BQ6: =IF(D6="","",IF(BO6-BP6>0,0,BO6-BP6)) | BR6: =IF(D6="","",IF(BO6-BP6-BN6>0,0,BO6-BP6-BN6)) | BS6: =IF(D6="","",IFERROR(AB6*AI6,0)) | BT6: =IF(D6="","",IFERROR(IF(X6>12, AI6*(U6+V6+X6), AI6*(U6+V6)),0)) | BU6: =IF(D6="","",IFERROR(((AB6*3)*AI6),0)) | BV6: =IF(D6="","",IF(BT6-BU6>0,0,BT6-BU6)) | BW6: =IF(D6="","",IF(BT6-BU6-BS6>0,0,BT6-BU6-BS6)) | BX6: =IF(D6="","",IFERROR(VLOOKUP(D6,'produto-entrada-7'!A:M,3,0),"SEM PEDIDO")) | BY6: =IF(D6="","",VLOOKUP(D6,'produto-estoque-total-7'!A:AB,25,0)) | BZ6: =IF(D6="","",IFERROR(VLOOKUP(D6,'produto-estoque-total-7'!A:AB,26,0)/100,0)) | CA6: =IF(D6="","",IFERROR(VLOOKUP(D6,'produto-estoque-total-7'!A:AB,27,0)/100,0)) | CB6: =IF(D6="","",V6*AF6) | CC6: =IF(D6="","",V6*AI6) | CD6: =IF(D6="","",VLOOKUP(D6,'produto-estoque-total-7'!A:AB,28,0))
A7: =IF(D7="","",VLOOKUP(D7,'produto-estoque-total-7'!A:AB,3,0)) | B7: =IF(D7="","",VLOOKUP(D7,'produto-estoque-total-7'!A:AB,12,0)) | C7: =IF(D7="","",VLOOKUP(D7,'produto-estoque-total-7'!A:AB,2,0)) | D7: =IFERROR(IF('produto-estoque-total-7'!A6="","",'produto-estoque-total-7'!A6),"") | E7: =IF(D7="","",VLOOKUP(D7,'produto-estoque-total-7'!A:AB,4,0)) | F7: =IF(D7="","",VLOOKUP(D7,'produto-estoque-total-7'!A:AB,13,0)) | G7: =IF(F7="","",VLOOKUP(F7,'FORNECEDORES X COMPRADOR'!A:D,4,0)) | H7: =IF(F7="","",VLOOKUP(F7,'FORNECEDORES X COMPRADOR'!A:E,5,0)) | I7: =IF(D7="","",VLOOKUP(D7,'produto-estoque-total-7'!A:AB,15,0)) | J7: =IF(D7="","",VLOOKUP(D7,'produto-estoque-total-7'!A:AB,19,0)) | K7: =IF(D7="","",VLOOKUP(D7,'produto-estoque-total-7'!A:AB,20,0)) | L7: =IF(D7="","",VLOOKUP(D7,'produto-estoque-total-7'!A:AB,17,0)) | M7: =IF(D7="","",VLOOKUP(D7,'produto-estoque-total-7'!A:AB,18,0)) | N7: =IF(D7="","",VLOOKUP(D7,'produto-estoque-total-7'!A:AB,21,0)) | O7: =IF(D7="","",VLOOKUP(D7,'produto-estoque-total-7'!A:AB,22,0)) | P7: =IF(D7="","",VLOOKUP(D7,'produto-estoque-total-7'!A:AB,23,0)) | Q7: =IF(D7="","",VLOOKUP(D7,'produto-estoque-total-7'!A:AB,24,0)) | R7: =IFERROR(IF(D7="","",VLOOKUP(D7,'produto-venda-7'!B:N,13,0)),"C") | S7: =IF(D7="","",VLOOKUP(D7,'produto-estoque-total-7'!A:AB,6,0)) | T7: =IF(D7="","",VLOOKUP(D7,'produto-estoque-total-7'!A:AB,5,0)) | U7: =IF(D7="","",VLOOKUP(D7,'produto-estoque-total-7'!A:AB,11,0)) | V7: =IF(D7="","",IFERROR(VLOOKUP(D7,'produto-entrada-7'!A:M,10,0),0)) | X7: =IF(D7="","",VLOOKUP(D7,'produto-estoque-total-7'!A:AB,8,0)) | Y7: =IF(D7="","",VLOOKUP(D7,'produto-estoque-total-7'!A:AB,9,0)) | Z7: =IF(D7="","",VLOOKUP(D7,'produto-estoque-total-7'!A:AB,10,0)) | AA7: =IFERROR(IF(D7="","",VLOOKUP(D7,'produto-venda-7'!B:N,4,0)),0) | AB7: =IFERROR(IF(D7="","",VLOOKUP(D7,'produto-venda-7'!B:N,5,0)),0) | AC7: =IF(D7="","",IFERROR(AA7/90,0)) | AD7: =IF(D7="","",IFERROR(VLOOKUP(D7,'produto-entrada-7'!A:M,4,0),0)) | AE7: =IFERROR(IF(D7="","",VLOOKUP(D7,'produto-venda-7'!B:N,10,0)),0) | AF7: =IF(D7="","",IFERROR(VLOOKUP(D7,'produto-entrada-7'!A:M,11,0),0)) | AG7: =IF(D7="","",IFERROR(VLOOKUP(D7,'produto-entrada-7'!A:M,12,0),0)) | AH7: =IF(D7="","",IFERROR(VLOOKUP(D7,'produto-entrada-7'!A:M,13,0),0)) | AI7: =IFERROR(IF(D7="","",VLOOKUP(D7,'produto-venda-7'!B:N,11,0)),0) | AJ7: =IF(D7="","",IFERROR(AI7*AB7,0)) | AK7: =IFERROR(IF(D7="","",VLOOKUP(F7,'ANALISE FORNECEDOR'!$A:$I,8,0)),"") | AL7: =IF(D7="","",AVERAGE(AM7,AK7)) | AM7: =IFERROR(IF(D7="","",VLOOKUP(F7,'ANALISE FORNECEDOR'!$A:$I,9,0)),"") | AN7: =IF(D7="","",IF(Y7>12,AI7*(U7+Y7),AI7*U7)) | AO7: =IF(D7="","",IF(Y7>12,AI7*(U7+V7+Y7),AI7*(U7+V7))) | AP7: =IF(D7="","",IF(Y7>12,AG7*(U7+Y7),AG7*U7)) | AQ7: =IF(D7="","",IF(Y7>12,AG7*(U7+V7+Y7),AG7*(U7+V7))) | AR7: =IF(D7="","",IF(OR(R7="A",R7="AA",R7="AAA"),AP7,0)) | AS7: =IF(D7="","",IF(R7="B",AP7,0)) | AT7: =IF(D7="","",IF(R7="C",AP7,0)) | AU7: =IF(D7="","",IFERROR(AN7/AJ7,0)) | AV7: =IF(D7="","",IFERROR(((AO7)/AJ7),0)) | AW7: =IF(D7="","",IF(OR(S7="S",NOT(AND(ISNUMBER(AC7),ISNUMBER(AL7),AC7*AL7>=0))),0,AC7*AL7)) | AX7: =IFERROR(IF(D7="","",AW7*AG7),0) | AY7: =IF(D7="","",IF(OR(S7="S",NOT(AND(ISNUMBER(AC7),ISNUMBER(AK7),AC7*AK7>=0))),0,AC7*AK7)) | AZ7: =IFERROR(IF(D7="","",IF(AY7=0,0,IF(((AY7)-(U7+Y7))<0,0,(AY7)-U7))),0) | BA7: =IF(D7="","",AZ7*AG7) | BB7: =IF(D7="","",IF(OR(R7="A",R7="AA",R7="AAA"),BA7,0)) | BC7: =IF(D7="","",IF(R7="B",BA7,0)) | BD7: =IF(D7="","",IF(R7="B",BA7,0)) | BE7: =IF(D7="","",IF(S7="S", 1, IF(AC7=0, 1, IF( IFERROR(((U7+Y7)*AG7)/((AC7*AK7)*AG7),0)<0, 0, IF( IFERROR(((U7+Y7)*AG7)/((AC7*AK7)*AG7),0)>1, 1, IFERROR(((U7+Y7)*AG7)/((AC7*AK7)*AG7),0) ) ) ) )) | BF7: =IF(D7="","",IF(S7="S", 1, IF(AC7=0, 1, IF( IFERROR(((U7+V7+Y7)*AG7)/((AC7*AK7)*AG7),0)<0, 0, IF( IFERROR(((U7+V7+Y7)*AG7)/((AC7*AK7)*AG7),0)>1, 1, IFERROR(((U7+V7+Y7)*AG7)/((AC7*AK7)*AG7),0) ) ) ) )) | BG7: =IF(D7="","",IF(S7="S",0,IF(AND(ISNUMBER(AC7),ISNUMBER(AM7)),IF(OR(AC7*AM7<0,ISERR(AC7*AM7)),0,AC7*AM7),0))) | BH7: =IF(D7="","",IF(BY7>TODAY()-60,0,IF(Y7>12,MAX(0,(U7+Y7)-BG7),MAX(0,U7-BG7)))) | BI7: =IF(D7="","",BH7*AG7) | BJ7: =IF(D7="","",IF(OR(R7="A",R7="AA",R7="AAA"),BI7,0)) | BK7: =IF(D7="","",IF(R7="B",BI7,0)) | BL7: =IF(D7="","",IF(R7="C",BI7,0)) | BM7: =IF(D7="","",IFERROR(MAX(0,MIN(BI7/AP7,1)),0)) | BN7: =IF(D7="","",AB7*AG7) | BO7: =IF(D7="","",(U7+V7+X7)*AG7) | BP7: =IF(D7="","",(AB7*3)*AG7) | BQ7: =IF(D7="","",IF(BO7-BP7>0,0,BO7-BP7)) | BR7: =IF(D7="","",IF(BO7-BP7-BN7>0,0,BO7-BP7-BN7)) | BS7: =IF(D7="","",IFERROR(AB7*AI7,0)) | BT7: =IF(D7="","",IFERROR(IF(X7>12, AI7*(U7+V7+X7), AI7*(U7+V7)),0)) | BU7: =IF(D7="","",IFERROR(((AB7*3)*AI7),0)) | BV7: =IF(D7="","",IF(BT7-BU7>0,0,BT7-BU7)) | BW7: =IF(D7="","",IF(BT7-BU7-BS7>0,0,BT7-BU7-BS7)) | BX7: =IF(D7="","",IFERROR(VLOOKUP(D7,'produto-entrada-7'!A:M,3,0),"SEM PEDIDO")) | BY7: =IF(D7="","",VLOOKUP(D7,'produto-estoque-total-7'!A:AB,25,0)) | BZ7: =IF(D7="","",IFERROR(VLOOKUP(D7,'produto-estoque-total-7'!A:AB,26,0)/100,0)) | CA7: =IF(D7="","",IFERROR(VLOOKUP(D7,'produto-estoque-total-7'!A:AB,27,0)/100,0)) | CB7: =IF(D7="","",V7*AF7) | CC7: =IF(D7="","",V7*AI7) | CD7: =IF(D7="","",VLOOKUP(D7,'produto-estoque-total-7'!A:AB,28,0))
A8: =IF(D8="","",VLOOKUP(D8,'produto-estoque-total-7'!A:AB,3,0)) | B8: =IF(D8="","",VLOOKUP(D8,'produto-estoque-total-7'!A:AB,12,0)) | C8: =IF(D8="","",VLOOKUP(D8,'produto-estoque-total-7'!A:AB,2,0)) | D8: =IFERROR(IF('produto-estoque-total-7'!A7="","",'produto-estoque-total-7'!A7),"") | E8: =IF(D8="","",VLOOKUP(D8,'produto-estoque-total-7'!A:AB,4,0)) | F8: =IF(D8="","",VLOOKUP(D8,'produto-estoque-total-7'!A:AB,13,0)) | G8: =IF(F8="","",VLOOKUP(F8,'FORNECEDORES X COMPRADOR'!A:D,4,0)) | H8: =IF(F8="","",VLOOKUP(F8,'FORNECEDORES X COMPRADOR'!A:E,5,0)) | I8: =IF(D8="","",VLOOKUP(D8,'produto-estoque-total-7'!A:AB,15,0)) | J8: =IF(D8="","",VLOOKUP(D8,'produto-estoque-total-7'!A:AB,19,0)) | K8: =IF(D8="","",VLOOKUP(D8,'produto-estoque-total-7'!A:AB,20,0)) | L8: =IF(D8="","",VLOOKUP(D8,'produto-estoque-total-7'!A:AB,17,0)) | M8: =IF(D8="","",VLOOKUP(D8,'produto-estoque-total-7'!A:AB,18,0)) | N8: =IF(D8="","",VLOOKUP(D8,'produto-estoque-total-7'!A:AB,21,0)) | O8: =IF(D8="","",VLOOKUP(D8,'produto-estoque-total-7'!A:AB,22,0)) | P8: =IF(D8="","",VLOOKUP(D8,'produto-estoque-total-7'!A:AB,23,0)) | Q8: =IF(D8="","",VLOOKUP(D8,'produto-estoque-total-7'!A:AB,24,0)) | R8: =IFERROR(IF(D8="","",VLOOKUP(D8,'produto-venda-7'!B:N,13,0)),"C") | S8: =IF(D8="","",VLOOKUP(D8,'produto-estoque-total-7'!A:AB,6,0)) | T8: =IF(D8="","",VLOOKUP(D8,'produto-estoque-total-7'!A:AB,5,0)) | U8: =IF(D8="","",VLOOKUP(D8,'produto-estoque-total-7'!A:AB,11,0)) | V8: =IF(D8="","",IFERROR(VLOOKUP(D8,'produto-entrada-7'!A:M,10,0),0)) | X8: =IF(D8="","",VLOOKUP(D8,'produto-estoque-total-7'!A:AB,8,0)) | Y8: =IF(D8="","",VLOOKUP(D8,'produto-estoque-total-7'!A:AB,9,0)) | Z8: =IF(D8="","",VLOOKUP(D8,'produto-estoque-total-7'!A:AB,10,0)) | AA8: =IFERROR(IF(D8="","",VLOOKUP(D8,'produto-venda-7'!B:N,4,0)),0) | AB8: =IFERROR(IF(D8="","",VLOOKUP(D8,'produto-venda-7'!B:N,5,0)),0) | AC8: =IF(D8="","",IFERROR(AA8/90,0)) | AD8: =IF(D8="","",IFERROR(VLOOKUP(D8,'produto-entrada-7'!A:M,4,0),0)) | AE8: =IFERROR(IF(D8="","",VLOOKUP(D8,'produto-venda-7'!B:N,10,0)),0) | AF8: =IF(D8="","",IFERROR(VLOOKUP(D8,'produto-entrada-7'!A:M,11,0),0)) | AG8: =IF(D8="","",IFERROR(VLOOKUP(D8,'produto-entrada-7'!A:M,12,0),0)) | AH8: =IF(D8="","",IFERROR(VLOOKUP(D8,'produto-entrada-7'!A:M,13,0),0)) | AI8: =IFERROR(IF(D8="","",VLOOKUP(D8,'produto-venda-7'!B:N,11,0)),0) | AJ8: =IF(D8="","",IFERROR(AI8*AB8,0)) | AK8: =IFERROR(IF(D8="","",VLOOKUP(F8,'ANALISE FORNECEDOR'!$A:$I,8,0)),"") | AL8: =IF(D8="","",AVERAGE(AM8,AK8)) | AM8: =IFERROR(IF(D8="","",VLOOKUP(F8,'ANALISE FORNECEDOR'!$A:$I,9,0)),"") | AN8: =IF(D8="","",IF(Y8>12,AI8*(U8+Y8),AI8*U8)) | AO8: =IF(D8="","",IF(Y8>12,AI8*(U8+V8+Y8),AI8*(U8+V8))) | AP8: =IF(D8="","",IF(Y8>12,AG8*(U8+Y8),AG8*U8)) | AQ8: =IF(D8="","",IF(Y8>12,AG8*(U8+V8+Y8),AG8*(U8+V8))) | AR8: =IF(D8="","",IF(OR(R8="A",R8="AA",R8="AAA"),AP8,0)) | AS8: =IF(D8="","",IF(R8="B",AP8,0)) | AT8: =IF(D8="","",IF(R8="C",AP8,0)) | AU8: =IF(D8="","",IFERROR(AN8/AJ8,0)) | AV8: =IF(D8="","",IFERROR(((AO8)/AJ8),0)) | AW8: =IF(D8="","",IF(OR(S8="S",NOT(AND(ISNUMBER(AC8),ISNUMBER(AL8),AC8*AL8>=0))),0,AC8*AL8)) | AX8: =IFERROR(IF(D8="","",AW8*AG8),0) | AY8: =IF(D8="","",IF(OR(S8="S",NOT(AND(ISNUMBER(AC8),ISNUMBER(AK8),AC8*AK8>=0))),0,AC8*AK8)) | AZ8: =IFERROR(IF(D8="","",IF(AY8=0,0,IF(((AY8)-(U8+Y8))<0,0,(AY8)-U8))),0) | BA8: =IF(D8="","",AZ8*AG8) | BB8: =IF(D8="","",IF(OR(R8="A",R8="AA",R8="AAA"),BA8,0)) | BC8: =IF(D8="","",IF(R8="B",BA8,0)) | BD8: =IF(D8="","",IF(R8="B",BA8,0)) | BE8: =IF(D8="","",IF(S8="S", 1, IF(AC8=0, 1, IF( IFERROR(((U8+Y8)*AG8)/((AC8*AK8)*AG8),0)<0, 0, IF( IFERROR(((U8+Y8)*AG8)/((AC8*AK8)*AG8),0)>1, 1, IFERROR(((U8+Y8)*AG8)/((AC8*AK8)*AG8),0) ) ) ) )) | BF8: =IF(D8="","",IF(S8="S", 1, IF(AC8=0, 1, IF( IFERROR(((U8+V8+Y8)*AG8)/((AC8*AK8)*AG8),0)<0, 0, IF( IFERROR(((U8+V8+Y8)*AG8)/((AC8*AK8)*AG8),0)>1, 1, IFERROR(((U8+V8+Y8)*AG8)/((AC8*AK8)*AG8),0) ) ) ) )) | BG8: =IF(D8="","",IF(S8="S",0,IF(AND(ISNUMBER(AC8),ISNUMBER(AM8)),IF(OR(AC8*AM8<0,ISERR(AC8*AM8)),0,AC8*AM8),0))) | BH8: =IF(D8="","",IF(BY8>TODAY()-60,0,IF(Y8>12,MAX(0,(U8+Y8)-BG8),MAX(0,U8-BG8)))) | BI8: =IF(D8="","",BH8*AG8) | BJ8: =IF(D8="","",IF(OR(R8="A",R8="AA",R8="AAA"),BI8,0)) | BK8: =IF(D8="","",IF(R8="B",BI8,0)) | BL8: =IF(D8="","",IF(R8="C",BI8,0)) | BM8: =IF(D8="","",IFERROR(MAX(0,MIN(BI8/AP8,1)),0)) | BN8: =IF(D8="","",AB8*AG8) | BO8: =IF(D8="","",(U8+V8+X8)*AG8) | BP8: =IF(D8="","",(AB8*3)*AG8) | BQ8: =IF(D8="","",IF(BO8-BP8>0,0,BO8-BP8)) | BR8: =IF(D8="","",IF(BO8-BP8-BN8>0,0,BO8-BP8-BN8)) | BS8: =IF(D8="","",IFERROR(AB8*AI8,0)) | BT8: =IF(D8="","",IFERROR(IF(X8>12, AI8*(U8+V8+X8), AI8*(U8+V8)),0)) | BU8: =IF(D8="","",IFERROR(((AB8*3)*AI8),0)) | BV8: =IF(D8="","",IF(BT8-BU8>0,0,BT8-BU8)) | BW8: =IF(D8="","",IF(BT8-BU8-BS8>0,0,BT8-BU8-BS8)) | BX8: =IF(D8="","",IFERROR(VLOOKUP(D8,'produto-entrada-7'!A:M,3,0),"SEM PEDIDO")) | BY8: =IF(D8="","",VLOOKUP(D8,'produto-estoque-total-7'!A:AB,25,0)) | BZ8: =IF(D8="","",IFERROR(VLOOKUP(D8,'produto-estoque-total-7'!A:AB,26,0)/100,0)) | CA8: =IF(D8="","",IFERROR(VLOOKUP(D8,'produto-estoque-total-7'!A:AB,27,0)/100,0)) | CB8: =IF(D8="","",V8*AF8) | CC8: =IF(D8="","",V8*AI8) | CD8: =IF(D8="","",VLOOKUP(D8,'produto-estoque-total-7'!A:AB,28,0))
A9: =IF(D9="","",VLOOKUP(D9,'produto-estoque-total-7'!A:AB,3,0)) | B9: =IF(D9="","",VLOOKUP(D9,'produto-estoque-total-7'!A:AB,12,0)) | C9: =IF(D9="","",VLOOKUP(D9,'produto-estoque-total-7'!A:AB,2,0)) | D9: =IFERROR(IF('produto-estoque-total-7'!A8="","",'produto-estoque-total-7'!A8),"") | E9: =IF(D9="","",VLOOKUP(D9,'produto-estoque-total-7'!A:AB,4,0)) | F9: =IF(D9="","",VLOOKUP(D9,'produto-estoque-total-7'!A:AB,13,0)) | G9: =IF(F9="","",VLOOKUP(F9,'FORNECEDORES X COMPRADOR'!A:D,4,0)) | H9: =IF(F9="","",VLOOKUP(F9,'FORNECEDORES X COMPRADOR'!A:E,5,0)) | I9: =IF(D9="","",VLOOKUP(D9,'produto-estoque-total-7'!A:AB,15,0)) | J9: =IF(D9="","",VLOOKUP(D9,'produto-estoque-total-7'!A:AB,19,0)) | K9: =IF(D9="","",VLOOKUP(D9,'produto-estoque-total-7'!A:AB,20,0)) | L9: =IF(D9="","",VLOOKUP(D9,'produto-estoque-total-7'!A:AB,17,0)) | M9: =IF(D9="","",VLOOKUP(D9,'produto-estoque-total-7'!A:AB,18,0)) | N9: =IF(D9="","",VLOOKUP(D9,'produto-estoque-total-7'!A:AB,21,0)) | O9: =IF(D9="","",VLOOKUP(D9,'produto-estoque-total-7'!A:AB,22,0)) | P9: =IF(D9="","",VLOOKUP(D9,'produto-estoque-total-7'!A:AB,23,0)) | Q9: =IF(D9="","",VLOOKUP(D9,'produto-estoque-total-7'!A:AB,24,0)) | R9: =IFERROR(IF(D9="","",VLOOKUP(D9,'produto-venda-7'!B:N,13,0)),"C") | S9: =IF(D9="","",VLOOKUP(D9,'produto-estoque-total-7'!A:AB,6,0)) | T9: =IF(D9="","",VLOOKUP(D9,'produto-estoque-total-7'!A:AB,5,0)) | U9: =IF(D9="","",VLOOKUP(D9,'produto-estoque-total-7'!A:AB,11,0)) | V9: =IF(D9="","",IFERROR(VLOOKUP(D9,'produto-entrada-7'!A:M,10,0),0)) | X9: =IF(D9="","",VLOOKUP(D9,'produto-estoque-total-7'!A:AB,8,0)) | Y9: =IF(D9="","",VLOOKUP(D9,'produto-estoque-total-7'!A:AB,9,0)) | Z9: =IF(D9="","",VLOOKUP(D9,'produto-estoque-total-7'!A:AB,10,0)) | AA9: =IFERROR(IF(D9="","",VLOOKUP(D9,'produto-venda-7'!B:N,4,0)),0) | AB9: =IFERROR(IF(D9="","",VLOOKUP(D9,'produto-venda-7'!B:N,5,0)),0) | AC9: =IF(D9="","",IFERROR(AA9/90,0)) | AD9: =IF(D9="","",IFERROR(VLOOKUP(D9,'produto-entrada-7'!A:M,4,0),0)) | AE9: =IFERROR(IF(D9="","",VLOOKUP(D9,'produto-venda-7'!B:N,10,0)),0) | AF9: =IF(D9="","",IFERROR(VLOOKUP(D9,'produto-entrada-7'!A:M,11,0),0)) | AG9: =IF(D9="","",IFERROR(VLOOKUP(D9,'produto-entrada-7'!A:M,12,0),0)) | AH9: =IF(D9="","",IFERROR(VLOOKUP(D9,'produto-entrada-7'!A:M,13,0),0)) | AI9: =IFERROR(IF(D9="","",VLOOKUP(D9,'produto-venda-7'!B:N,11,0)),0) | AJ9: =IF(D9="","",IFERROR(AI9*AB9,0)) | AK9: =IFERROR(IF(D9="","",VLOOKUP(F9,'ANALISE FORNECEDOR'!$A:$I,8,0)),"") | AL9: =IF(D9="","",AVERAGE(AM9,AK9)) | AM9: =IFERROR(IF(D9="","",VLOOKUP(F9,'ANALISE FORNECEDOR'!$A:$I,9,0)),"") | AN9: =IF(D9="","",IF(Y9>12,AI9*(U9+Y9),AI9*U9)) | AO9: =IF(D9="","",IF(Y9>12,AI9*(U9+V9+Y9),AI9*(U9+V9))) | AP9: =IF(D9="","",IF(Y9>12,AG9*(U9+Y9),AG9*U9)) | AQ9: =IF(D9="","",IF(Y9>12,AG9*(U9+V9+Y9),AG9*(U9+V9))) | AR9: =IF(D9="","",IF(OR(R9="A",R9="AA",R9="AAA"),AP9,0)) | AS9: =IF(D9="","",IF(R9="B",AP9,0)) | AT9: =IF(D9="","",IF(R9="C",AP9,0)) | AU9: =IF(D9="","",IFERROR(AN9/AJ9,0)) | AV9: =IF(D9="","",IFERROR(((AO9)/AJ9),0)) | AW9: =IF(D9="","",IF(OR(S9="S",NOT(AND(ISNUMBER(AC9),ISNUMBER(AL9),AC9*AL9>=0))),0,AC9*AL9)) | AX9: =IFERROR(IF(D9="","",AW9*AG9),0) | AY9: =IF(D9="","",IF(OR(S9="S",NOT(AND(ISNUMBER(AC9),ISNUMBER(AK9),AC9*AK9>=0))),0,AC9*AK9)) | AZ9: =IFERROR(IF(D9="","",IF(AY9=0,0,IF(((AY9)-(U9+Y9))<0,0,(AY9)-U9))),0) | BA9: =IF(D9="","",AZ9*AG9) | BB9: =IF(D9="","",IF(OR(R9="A",R9="AA",R9="AAA"),BA9,0)) | BC9: =IF(D9="","",IF(R9="B",BA9,0)) | BD9: =IF(D9="","",IF(R9="B",BA9,0)) | BE9: =IF(D9="","",IF(S9="S", 1, IF(AC9=0, 1, IF( IFERROR(((U9+Y9)*AG9)/((AC9*AK9)*AG9),0)<0, 0, IF( IFERROR(((U9+Y9)*AG9)/((AC9*AK9)*AG9),0)>1, 1, IFERROR(((U9+Y9)*AG9)/((AC9*AK9)*AG9),0) ) ) ) )) | BF9: =IF(D9="","",IF(S9="S", 1, IF(AC9=0, 1, IF( IFERROR(((U9+V9+Y9)*AG9)/((AC9*AK9)*AG9),0)<0, 0, IF( IFERROR(((U9+V9+Y9)*AG9)/((AC9*AK9)*AG9),0)>1, 1, IFERROR(((U9+V9+Y9)*AG9)/((AC9*AK9)*AG9),0) ) ) ) )) | BG9: =IF(D9="","",IF(S9="S",0,IF(AND(ISNUMBER(AC9),ISNUMBER(AM9)),IF(OR(AC9*AM9<0,ISERR(AC9*AM9)),0,AC9*AM9),0))) | BH9: =IF(D9="","",IF(BY9>TODAY()-60,0,IF(Y9>12,MAX(0,(U9+Y9)-BG9),MAX(0,U9-BG9)))) | BI9: =IF(D9="","",BH9*AG9) | BJ9: =IF(D9="","",IF(OR(R9="A",R9="AA",R9="AAA"),BI9,0)) | BK9: =IF(D9="","",IF(R9="B",BI9,0)) | BL9: =IF(D9="","",IF(R9="C",BI9,0)) | BM9: =IF(D9="","",IFERROR(MAX(0,MIN(BI9/AP9,1)),0)) | BN9: =IF(D9="","",AB9*AG9) | BO9: =IF(D9="","",(U9+V9+X9)*AG9) | BP9: =IF(D9="","",(AB9*3)*AG9) | BQ9: =IF(D9="","",IF(BO9-BP9>0,0,BO9-BP9)) | BR9: =IF(D9="","",IF(BO9-BP9-BN9>0,0,BO9-BP9-BN9)) | BS9: =IF(D9="","",IFERROR(AB9*AI9,0)) | BT9: =IF(D9="","",IFERROR(IF(X9>12, AI9*(U9+V9+X9), AI9*(U9+V9)),0)) | BU9: =IF(D9="","",IFERROR(((AB9*3)*AI9),0)) | BV9: =IF(D9="","",IF(BT9-BU9>0,0,BT9-BU9)) | BW9: =IF(D9="","",IF(BT9-BU9-BS9>0,0,BT9-BU9-BS9)) | BX9: =IF(D9="","",IFERROR(VLOOKUP(D9,'produto-entrada-7'!A:M,3,0),"SEM PEDIDO")) | BY9: =IF(D9="","",VLOOKUP(D9,'produto-estoque-total-7'!A:AB,25,0)) | BZ9: =IF(D9="","",IFERROR(VLOOKUP(D9,'produto-estoque-total-7'!A:AB,26,0)/100,0)) | CA9: =IF(D9="","",IFERROR(VLOOKUP(D9,'produto-estoque-total-7'!A:AB,27,0)/100,0)) | CB9: =IF(D9="","",V9*AF9) | CC9: =IF(D9="","",V9*AI9) | CD9: =IF(D9="","",VLOOKUP(D9,'produto-estoque-total-7'!A:AB,28,0))
A10: =IF(D10="","",VLOOKUP(D10,'produto-estoque-total-7'!A:AB,3,0)) | B10: =IF(D10="","",VLOOKUP(D10,'produto-estoque-total-7'!A:AB,12,0)) | C10: =IF(D10="","",VLOOKUP(D10,'produto-estoque-total-7'!A:AB,2,0)) | D10: =IFERROR(IF('produto-estoque-total-7'!A9="","",'produto-estoque-total-7'!A9),"") | E10: =IF(D10="","",VLOOKUP(D10,'produto-estoque-total-7'!A:AB,4,0)) | F10: =IF(D10="","",VLOOKUP(D10,'produto-estoque-total-7'!A:AB,13,0)) | G10: =IF(F10="","",VLOOKUP(F10,'FORNECEDORES X COMPRADOR'!A:D,4,0)) | H10: =IF(F10="","",VLOOKUP(F10,'FORNECEDORES X COMPRADOR'!A:E,5,0)) | I10: =IF(D10="","",VLOOKUP(D10,'produto-estoque-total-7'!A:AB,15,0)) | J10: =IF(D10="","",VLOOKUP(D10,'produto-estoque-total-7'!A:AB,19,0)) | K10: =IF(D10="","",VLOOKUP(D10,'produto-estoque-total-7'!A:AB,20,0)) | L10: =IF(D10="","",VLOOKUP(D10,'produto-estoque-total-7'!A:AB,17,0)) | M10: =IF(D10="","",VLOOKUP(D10,'produto-estoque-total-7'!A:AB,18,0)) | N10: =IF(D10="","",VLOOKUP(D10,'produto-estoque-total-7'!A:AB,21,0)) | O10: =IF(D10="","",VLOOKUP(D10,'produto-estoque-total-7'!A:AB,22,0)) | P10: =IF(D10="","",VLOOKUP(D10,'produto-estoque-total-7'!A:AB,23,0)) | Q10: =IF(D10="","",VLOOKUP(D10,'produto-estoque-total-7'!A:AB,24,0)) | R10: =IFERROR(IF(D10="","",VLOOKUP(D10,'produto-venda-7'!B:N,13,0)),"C") | S10: =IF(D10="","",VLOOKUP(D10,'produto-estoque-total-7'!A:AB,6,0)) | T10: =IF(D10="","",VLOOKUP(D10,'produto-estoque-total-7'!A:AB,5,0)) | U10: =IF(D10="","",VLOOKUP(D10,'produto-estoque-total-7'!A:AB,11,0)) | V10: =IF(D10="","",IFERROR(VLOOKUP(D10,'produto-entrada-7'!A:M,10,0),0)) | X10: =IF(D10="","",VLOOKUP(D10,'produto-estoque-total-7'!A:AB,8,0)) | Y10: =IF(D10="","",VLOOKUP(D10,'produto-estoque-total-7'!A:AB,9,0)) | Z10: =IF(D10="","",VLOOKUP(D10,'produto-estoque-total-7'!A:AB,10,0)) | AA10: =IFERROR(IF(D10="","",VLOOKUP(D10,'produto-venda-7'!B:N,4,0)),0) | AB10: =IFERROR(IF(D10="","",VLOOKUP(D10,'produto-venda-7'!B:N,5,0)),0) | AC10: =IF(D10="","",IFERROR(AA10/90,0)) | AD10: =IF(D10="","",IFERROR(VLOOKUP(D10,'produto-entrada-7'!A:M,4,0),0)) | AE10: =IFERROR(IF(D10="","",VLOOKUP(D10,'produto-venda-7'!B:N,10,0)),0) | AF10: =IF(D10="","",IFERROR(VLOOKUP(D10,'produto-entrada-7'!A:M,11,0),0)) | AG10: =IF(D10="","",IFERROR(VLOOKUP(D10,'produto-entrada-7'!A:M,12,0),0)) | AH10: =IF(D10="","",IFERROR(VLOOKUP(D10,'produto-entrada-7'!A:M,13,0),0)) | AI10: =IFERROR(IF(D10="","",VLOOKUP(D10,'produto-venda-7'!B:N,11,0)),0) | AJ10: =IF(D10="","",IFERROR(AI10*AB10,0)) | AK10: =IFERROR(IF(D10="","",VLOOKUP(F10,'ANALISE FORNECEDOR'!$A:$I,8,0)),"") | AL10: =IF(D10="","",AVERAGE(AM10,AK10)) | AM10: =IFERROR(IF(D10="","",VLOOKUP(F10,'ANALISE FORNECEDOR'!$A:$I,9,0)),"") | AN10: =IF(D10="","",IF(Y10>12,AI10*(U10+Y10),AI10*U10)) | AO10: =IF(D10="","",IF(Y10>12,AI10*(U10+V10+Y10),AI10*(U10+V10))) | AP10: =IF(D10="","",IF(Y10>12,AG10*(U10+Y10),AG10*U10)) | AQ10: =IF(D10="","",IF(Y10>12,AG10*(U10+V10+Y10),AG10*(U10+V10))) | AR10: =IF(D10="","",IF(OR(R10="A",R10="AA",R10="AAA"),AP10,0)) | AS10: =IF(D10="","",IF(R10="B",AP10,0)) | AT10: =IF(D10="","",IF(R10="C",AP10,0)) | AU10: =IF(D10="","",IFERROR(AN10/AJ10,0)) | AV10: =IF(D10="","",IFERROR(((AO10)/AJ10),0)) | AW10: =IF(D10="","",IF(OR(S10="S",NOT(AND(ISNUMBER(AC10),ISNUMBER(AL10),AC10*AL10>=0))),0,AC10*AL10)) | AX10: =IFERROR(IF(D10="","",AW10*AG10),0) | AY10: =IF(D10="","",IF(OR(S10="S",NOT(AND(ISNUMBER(AC10),ISNUMBER(AK10),AC10*AK10>=0))),0,AC10*AK10)) | AZ10: =IFERROR(IF(D10="","",IF(AY10=0,0,IF(((AY10)-(U10+Y10))<0,0,(AY10)-U10))),0) | BA10: =IF(D10="","",AZ10*AG10) | BB10: =IF(D10="","",IF(OR(R10="A",R10="AA",R10="AAA"),BA10,0)) | BC10: =IF(D10="","",IF(R10="B",BA10,0)) | BD10: =IF(D10="","",IF(R10="B",BA10,0)) | BE10: =IF(D10="","",IF(S10="S", 1, IF(AC10=0, 1, IF( IFERROR(((U10+Y10)*AG10)/((AC10*AK10)*AG10),0)<0, 0, IF( IFERROR(((U10+Y10)*AG10)/((AC10*AK10)*AG10),0)>1, 1, IFERROR(((U10+Y10)*AG10)/((AC10*AK10)*AG10),0) ) ) ) )) | BF10: =IF(D10="","",IF(S10="S", 1, IF(AC10=0, 1, IF( IFERROR(((U10+V10+Y10)*AG10)/((AC10*AK10)*AG10),0)<0, 0, IF( IFERROR(((U10+V10+Y10)*AG10)/((AC10*AK10)*AG10),0)>1, 1, IFERROR(((U10+V10+Y10)*AG10)/((AC10*AK10)*AG10),0) ) ) ) )) | BG10: =IF(D10="","",IF(S10="S",0,IF(AND(ISNUMBER(AC10),ISNUMBER(AM10)),IF(OR(AC10*AM10<0,ISERR(AC10*AM10)),0,AC10*AM10),0))) | BH10: =IF(D10="","",IF(BY10>TODAY()-60,0,IF(Y10>12,MAX(0,(U10+Y10)-BG10),MAX(0,U10-BG10)))) | BI10: =IF(D10="","",BH10*AG10) | BJ10: =IF(D10="","",IF(OR(R10="A",R10="AA",R10="AAA"),BI10,0)) | BK10: =IF(D10="","",IF(R10="B",BI10,0)) | BL10: =IF(D10="","",IF(R10="C",BI10,0)) | BM10: =IF(D10="","",IFERROR(MAX(0,MIN(BI10/AP10,1)),0)) | BN10: =IF(D10="","",AB10*AG10) | BO10: =IF(D10="","",(U10+V10+X10)*AG10) | BP10: =IF(D10="","",(AB10*3)*AG10) | BQ10: =IF(D10="","",IF(BO10-BP10>0,0,BO10-BP10)) | BR10: =IF(D10="","",IF(BO10-BP10-BN10>0,0,BO10-BP10-BN10)) | BS10: =IF(D10="","",IFERROR(AB10*AI10,0)) | BT10: =IF(D10="","",IFERROR(IF(X10>12, AI10*(U10+V10+X10), AI10*(U10+V10)),0)) | BU10: =IF(D10="","",IFERROR(((AB10*3)*AI10),0)) | BV10: =IF(D10="","",IF(BT10-BU10>0,0,BT10-BU10)) | BW10: =IF(D10="","",IF(BT10-BU10-BS10>0,0,BT10-BU10-BS10)) | BX10: =IF(D10="","",IFERROR(VLOOKUP(D10,'produto-entrada-7'!A:M,3,0),"SEM PEDIDO")) | BY10: =IF(D10="","",VLOOKUP(D10,'produto-estoque-total-7'!A:AB,25,0)) | BZ10: =IF(D10="","",IFERROR(VLOOKUP(D10,'produto-estoque-total-7'!A:AB,26,0)/100,0)) | CA10: =IF(D10="","",IFERROR(VLOOKUP(D10,'produto-estoque-total-7'!A:AB,27,0)/100,0)) | CB10: =IF(D10="","",V10*AF10) | CC10: =IF(D10="","",V10*AI10) | CD10: =IF(D10="","",VLOOKUP(D10,'produto-estoque-total-7'!A:AB,28,0))
A11: =IF(D11="","",VLOOKUP(D11,'produto-estoque-total-7'!A:AB,3,0)) | B11: =IF(D11="","",VLOOKUP(D11,'produto-estoque-total-7'!A:AB,12,0)) | C11: =IF(D11="","",VLOOKUP(D11,'produto-estoque-total-7'!A:AB,2,0)) | D11: =IFERROR(IF('produto-estoque-total-7'!A10="","",'produto-estoque-total-7'!A10),"") | E11: =IF(D11="","",VLOOKUP(D11,'produto-estoque-total-7'!A:AB,4,0)) | F11: =IF(D11="","",VLOOKUP(D11,'produto-estoque-total-7'!A:AB,13,0)) | G11: =IF(F11="","",VLOOKUP(F11,'FORNECEDORES X COMPRADOR'!A:D,4,0)) | H11: =IF(F11="","",VLOOKUP(F11,'FORNECEDORES X COMPRADOR'!A:E,5,0)) | I11: =IF(D11="","",VLOOKUP(D11,'produto-estoque-total-7'!A:AB,15,0)) | J11: =IF(D11="","",VLOOKUP(D11,'produto-estoque-total-7'!A:AB,19,0)) | K11: =IF(D11="","",VLOOKUP(D11,'produto-estoque-total-7'!A:AB,20,0)) | L11: =IF(D11="","",VLOOKUP(D11,'produto-estoque-total-7'!A:AB,17,0)) | M11: =IF(D11="","",VLOOKUP(D11,'produto-estoque-total-7'!A:AB,18,0)) | N11: =IF(D11="","",VLOOKUP(D11,'produto-estoque-total-7'!A:AB,21,0)) | O11: =IF(D11="","",VLOOKUP(D11,'produto-estoque-total-7'!A:AB,22,0)) | P11: =IF(D11="","",VLOOKUP(D11,'produto-estoque-total-7'!A:AB,23,0)) | Q11: =IF(D11="","",VLOOKUP(D11,'produto-estoque-total-7'!A:AB,24,0)) | R11: =IFERROR(IF(D11="","",VLOOKUP(D11,'produto-venda-7'!B:N,13,0)),"C") | S11: =IF(D11="","",VLOOKUP(D11,'produto-estoque-total-7'!A:AB,6,0)) | T11: =IF(D11="","",VLOOKUP(D11,'produto-estoque-total-7'!A:AB,5,0)) | U11: =IF(D11="","",VLOOKUP(D11,'produto-estoque-total-7'!A:AB,11,0)) | V11: =IF(D11="","",IFERROR(VLOOKUP(D11,'produto-entrada-7'!A:M,10,0),0)) | X11: =IF(D11="","",VLOOKUP(D11,'produto-estoque-total-7'!A:AB,8,0)) | Y11: =IF(D11="","",VLOOKUP(D11,'produto-estoque-total-7'!A:AB,9,0)) | Z11: =IF(D11="","",VLOOKUP(D11,'produto-estoque-total-7'!A:AB,10,0)) | AA11: =IFERROR(IF(D11="","",VLOOKUP(D11,'produto-venda-7'!B:N,4,0)),0) | AB11: =IFERROR(IF(D11="","",VLOOKUP(D11,'produto-venda-7'!B:N,5,0)),0) | AC11: =IF(D11="","",IFERROR(AA11/90,0)) | AD11: =IF(D11="","",IFERROR(VLOOKUP(D11,'produto-entrada-7'!A:M,4,0),0)) | AE11: =IFERROR(IF(D11="","",VLOOKUP(D11,'produto-venda-7'!B:N,10,0)),0) | AF11: =IF(D11="","",IFERROR(VLOOKUP(D11,'produto-entrada-7'!A:M,11,0),0)) | AG11: =IF(D11="","",IFERROR(VLOOKUP(D11,'produto-entrada-7'!A:M,12,0),0)) | AH11: =IF(D11="","",IFERROR(VLOOKUP(D11,'produto-entrada-7'!A:M,13,0),0)) | AI11: =IFERROR(IF(D11="","",VLOOKUP(D11,'produto-venda-7'!B:N,11,0)),0) | AJ11: =IF(D11="","",IFERROR(AI11*AB11,0)) | AK11: =IFERROR(IF(D11="","",VLOOKUP(F11,'ANALISE FORNECEDOR'!$A:$I,8,0)),"") | AL11: =IF(D11="","",AVERAGE(AM11,AK11)) | AM11: =IFERROR(IF(D11="","",VLOOKUP(F11,'ANALISE FORNECEDOR'!$A:$I,9,0)),"") | AN11: =IF(D11="","",IF(Y11>12,AI11*(U11+Y11),AI11*U11)) | AO11: =IF(D11="","",IF(Y11>12,AI11*(U11+V11+Y11),AI11*(U11+V11))) | AP11: =IF(D11="","",IF(Y11>12,AG11*(U11+Y11),AG11*U11)) | AQ11: =IF(D11="","",IF(Y11>12,AG11*(U11+V11+Y11),AG11*(U11+V11))) | AR11: =IF(D11="","",IF(OR(R11="A",R11="AA",R11="AAA"),AP11,0)) | AS11: =IF(D11="","",IF(R11="B",AP11,0)) | AT11: =IF(D11="","",IF(R11="C",AP11,0)) | AU11: =IF(D11="","",IFERROR(AN11/AJ11,0)) | AV11: =IF(D11="","",IFERROR(((AO11)/AJ11),0)) | AW11: =IF(D11="","",IF(OR(S11="S",NOT(AND(ISNUMBER(AC11),ISNUMBER(AL11),AC11*AL11>=0))),0,AC11*AL11)) | AX11: =IFERROR(IF(D11="","",AW11*AG11),0) | AY11: =IF(D11="","",IF(OR(S11="S",NOT(AND(ISNUMBER(AC11),ISNUMBER(AK11),AC11*AK11>=0))),0,AC11*AK11)) | AZ11: =IFERROR(IF(D11="","",IF(AY11=0,0,IF(((AY11)-(U11+Y11))<0,0,(AY11)-U11))),0) | BA11: =IF(D11="","",AZ11*AG11) | BB11: =IF(D11="","",IF(OR(R11="A",R11="AA",R11="AAA"),BA11,0)) | BC11: =IF(D11="","",IF(R11="B",BA11,0)) | BD11: =IF(D11="","",IF(R11="B",BA11,0)) | BE11: =IF(D11="","",IF(S11="S", 1, IF(AC11=0, 1, IF( IFERROR(((U11+Y11)*AG11)/((AC11*AK11)*AG11),0)<0, 0, IF( IFERROR(((U11+Y11)*AG11)/((AC11*AK11)*AG11),0)>1, 1, IFERROR(((U11+Y11)*AG11)/((AC11*AK11)*AG11),0) ) ) ) )) | BF11: =IF(D11="","",IF(S11="S", 1, IF(AC11=0, 1, IF( IFERROR(((U11+V11+Y11)*AG11)/((AC11*AK11)*AG11),0)<0, 0, IF( IFERROR(((U11+V11+Y11)*AG11)/((AC11*AK11)*AG11),0)>1, 1, IFERROR(((U11+V11+Y11)*AG11)/((AC11*AK11)*AG11),0) ) ) ) )) | BG11: =IF(D11="","",IF(S11="S",0,IF(AND(ISNUMBER(AC11),ISNUMBER(AM11)),IF(OR(AC11*AM11<0,ISERR(AC11*AM11)),0,AC11*AM11),0))) | BH11: =IF(D11="","",IF(BY11>TODAY()-60,0,IF(Y11>12,MAX(0,(U11+Y11)-BG11),MAX(0,U11-BG11)))) | BI11: =IF(D11="","",BH11*AG11) | BJ11: =IF(D11="","",IF(OR(R11="A",R11="AA",R11="AAA"),BI11,0)) | BK11: =IF(D11="","",IF(R11="B",BI11,0)) | BL11: =IF(D11="","",IF(R11="C",BI11,0)) | BM11: =IF(D11="","",IFERROR(MAX(0,MIN(BI11/AP11,1)),0)) | BN11: =IF(D11="","",AB11*AG11) | BO11: =IF(D11="","",(U11+V11+X11)*AG11) | BP11: =IF(D11="","",(AB11*3)*AG11) | BQ11: =IF(D11="","",IF(BO11-BP11>0,0,BO11-BP11)) | BR11: =IF(D11="","",IF(BO11-BP11-BN11>0,0,BO11-BP11-BN11)) | BS11: =IF(D11="","",IFERROR(AB11*AI11,0)) | BT11: =IF(D11="","",IFERROR(IF(X11>12, AI11*(U11+V11+X11), AI11*(U11+V11)),0)) | BU11: =IF(D11="","",IFERROR(((AB11*3)*AI11),0)) | BV11: =IF(D11="","",IF(BT11-BU11>0,0,BT11-BU11)) | BW11: =IF(D11="","",IF(BT11-BU11-BS11>0,0,BT11-BU11-BS11)) | BX11: =IF(D11="","",IFERROR(VLOOKUP(D11,'produto-entrada-7'!A:M,3,0),"SEM PEDIDO")) | BY11: =IF(D11="","",VLOOKUP(D11,'produto-estoque-total-7'!A:AB,25,0)) | BZ11: =IF(D11="","",IFERROR(VLOOKUP(D11,'produto-estoque-total-7'!A:AB,26,0)/100,0)) | CA11: =IF(D11="","",IFERROR(VLOOKUP(D11,'produto-estoque-total-7'!A:AB,27,0)/100,0)) | CB11: =IF(D11="","",V11*AF11) | CC11: =IF(D11="","",V11*AI11) | CD11: =IF(D11="","",VLOOKUP(D11,'produto-estoque-total-7'!A:AB,28,0))
A12: =IF(D12="","",VLOOKUP(D12,'produto-estoque-total-7'!A:AB,3,0)) | B12: =IF(D12="","",VLOOKUP(D12,'produto-estoque-total-7'!A:AB,12,0)) | C12: =IF(D12="","",VLOOKUP(D12,'produto-estoque-total-7'!A:AB,2,0)) | D12: =IFERROR(IF('produto-estoque-total-7'!A11="","",'produto-estoque-total-7'!A11),"") | E12: =IF(D12="","",VLOOKUP(D12,'produto-estoque-total-7'!A:AB,4,0)) | F12: =IF(D12="","",VLOOKUP(D12,'produto-estoque-total-7'!A:AB,13,0)) | G12: =IF(F12="","",VLOOKUP(F12,'FORNECEDORES X COMPRADOR'!A:D,4,0)) | H12: =IF(F12="","",VLOOKUP(F12,'FORNECEDORES X COMPRADOR'!A:E,5,0)) | I12: =IF(D12="","",VLOOKUP(D12,'produto-estoque-total-7'!A:AB,15,0)) | J12: =IF(D12="","",VLOOKUP(D12,'produto-estoque-total-7'!A:AB,19,0)) | K12: =IF(D12="","",VLOOKUP(D12,'produto-estoque-total-7'!A:AB,20,0)) | L12: =IF(D12="","",VLOOKUP(D12,'produto-estoque-total-7'!A:AB,17,0)) | M12: =IF(D12="","",VLOOKUP(D12,'produto-estoque-total-7'!A:AB,18,0)) | N12: =IF(D12="","",VLOOKUP(D12,'produto-estoque-total-7'!A:AB,21,0)) | O12: =IF(D12="","",VLOOKUP(D12,'produto-estoque-total-7'!A:AB,22,0)) | P12: =IF(D12="","",VLOOKUP(D12,'produto-estoque-total-7'!A:AB,23,0)) | Q12: =IF(D12="","",VLOOKUP(D12,'produto-estoque-total-7'!A:AB,24,0)) | R12: =IFERROR(IF(D12="","",VLOOKUP(D12,'produto-venda-7'!B:N,13,0)),"C") | S12: =IF(D12="","",VLOOKUP(D12,'produto-estoque-total-7'!A:AB,6,0)) | T12: =IF(D12="","",VLOOKUP(D12,'produto-estoque-total-7'!A:AB,5,0)) | U12: =IF(D12="","",VLOOKUP(D12,'produto-estoque-total-7'!A:AB,11,0)) | V12: =IF(D12="","",IFERROR(VLOOKUP(D12,'produto-entrada-7'!A:M,10,0),0)) | X12: =IF(D12="","",VLOOKUP(D12,'produto-estoque-total-7'!A:AB,8,0)) | Y12: =IF(D12="","",VLOOKUP(D12,'produto-estoque-total-7'!A:AB,9,0)) | Z12: =IF(D12="","",VLOOKUP(D12,'produto-estoque-total-7'!A:AB,10,0)) | AA12: =IFERROR(IF(D12="","",VLOOKUP(D12,'produto-venda-7'!B:N,4,0)),0) | AB12: =IFERROR(IF(D12="","",VLOOKUP(D12,'produto-venda-7'!B:N,5,0)),0) | AC12: =IF(D12="","",IFERROR(AA12/90,0)) | AD12: =IF(D12="","",IFERROR(VLOOKUP(D12,'produto-entrada-7'!A:M,4,0),0)) | AE12: =IFERROR(IF(D12="","",VLOOKUP(D12,'produto-venda-7'!B:N,10,0)),0) | AF12: =IF(D12="","",IFERROR(VLOOKUP(D12,'produto-entrada-7'!A:M,11,0),0)) | AG12: =IF(D12="","",IFERROR(VLOOKUP(D12,'produto-entrada-7'!A:M,12,0),0)) | AH12: =IF(D12="","",IFERROR(VLOOKUP(D12,'produto-entrada-7'!A:M,13,0),0)) | AI12: =IFERROR(IF(D12="","",VLOOKUP(D12,'produto-venda-7'!B:N,11,0)),0) | AJ12: =IF(D12="","",IFERROR(AI12*AB12,0)) | AK12: =IFERROR(IF(D12="","",VLOOKUP(F12,'ANALISE FORNECEDOR'!$A:$I,8,0)),"") | AL12: =IF(D12="","",AVERAGE(AM12,AK12)) | AM12: =IFERROR(IF(D12="","",VLOOKUP(F12,'ANALISE FORNECEDOR'!$A:$I,9,0)),"") | AN12: =IF(D12="","",IF(Y12>12,AI12*(U12+Y12),AI12*U12)) | AO12: =IF(D12="","",IF(Y12>12,AI12*(U12+V12+Y12),AI12*(U12+V12))) | AP12: =IF(D12="","",IF(Y12>12,AG12*(U12+Y12),AG12*U12)) | AQ12: =IF(D12="","",IF(Y12>12,AG12*(U12+V12+Y12),AG12*(U12+V12))) | AR12: =IF(D12="","",IF(OR(R12="A",R12="AA",R12="AAA"),AP12,0)) | AS12: =IF(D12="","",IF(R12="B",AP12,0)) | AT12: =IF(D12="","",IF(R12="C",AP12,0)) | AU12: =IF(D12="","",IFERROR(AN12/AJ12,0)) | AV12: =IF(D12="","",IFERROR(((AO12)/AJ12),0)) | AW12: =IF(D12="","",IF(OR(S12="S",NOT(AND(ISNUMBER(AC12),ISNUMBER(AL12),AC12*AL12>=0))),0,AC12*AL12)) | AX12: =IFERROR(IF(D12="","",AW12*AG12),0) | AY12: =IF(D12="","",IF(OR(S12="S",NOT(AND(ISNUMBER(AC12),ISNUMBER(AK12),AC12*AK12>=0))),0,AC12*AK12)) | AZ12: =IFERROR(IF(D12="","",IF(AY12=0,0,IF(((AY12)-(U12+Y12))<0,0,(AY12)-U12))),0) | BA12: =IF(D12="","",AZ12*AG12) | BB12: =IF(D12="","",IF(OR(R12="A",R12="AA",R12="AAA"),BA12,0)) | BC12: =IF(D12="","",IF(R12="B",BA12,0)) | BD12: =IF(D12="","",IF(R12="B",BA12,0)) | BE12: =IF(D12="","",IF(S12="S", 1, IF(AC12=0, 1, IF( IFERROR(((U12+Y12)*AG12)/((AC12*AK12)*AG12),0)<0, 0, IF( IFERROR(((U12+Y12)*AG12)/((AC12*AK12)*AG12),0)>1, 1, IFERROR(((U12+Y12)*AG12)/((AC12*AK12)*AG12),0) ) ) ) )) | BF12: =IF(D12="","",IF(S12="S", 1, IF(AC12=0, 1, IF( IFERROR(((U12+V12+Y12)*AG12)/((AC12*AK12)*AG12),0)<0, 0, IF( IFERROR(((U12+V12+Y12)*AG12)/((AC12*AK12)*AG12),0)>1, 1, IFERROR(((U12+V12+Y12)*AG12)/((AC12*AK12)*AG12),0) ) ) ) )) | BG12: =IF(D12="","",IF(S12="S",0,IF(AND(ISNUMBER(AC12),ISNUMBER(AM12)),IF(OR(AC12*AM12<0,ISERR(AC12*AM12)),0,AC12*AM12),0))) | BH12: =IF(D12="","",IF(BY12>TODAY()-60,0,IF(Y12>12,MAX(0,(U12+Y12)-BG12),MAX(0,U12-BG12)))) | BI12: =IF(D12="","",BH12*AG12) | BJ12: =IF(D12="","",IF(OR(R12="A",R12="AA",R12="AAA"),BI12,0)) | BK12: =IF(D12="","",IF(R12="B",BI12,0)) | BL12: =IF(D12="","",IF(R12="C",BI12,0)) | BM12: =IF(D12="","",IFERROR(MAX(0,MIN(BI12/AP12,1)),0)) | BN12: =IF(D12="","",AB12*AG12) | BO12: =IF(D12="","",(U12+V12+X12)*AG12) | BP12: =IF(D12="","",(AB12*3)*AG12) | BQ12: =IF(D12="","",IF(BO12-BP12>0,0,BO12-BP12)) | BR12: =IF(D12="","",IF(BO12-BP12-BN12>0,0,BO12-BP12-BN12)) | BS12: =IF(D12="","",IFERROR(AB12*AI12,0)) | BT12: =IF(D12="","",IFERROR(IF(X12>12, AI12*(U12+V12+X12), AI12*(U12+V12)),0)) | BU12: =IF(D12="","",IFERROR(((AB12*3)*AI12),0)) | BV12: =IF(D12="","",IF(BT12-BU12>0,0,BT12-BU12)) | BW12: =IF(D12="","",IF(BT12-BU12-BS12>0,0,BT12-BU12-BS12)) | BX12: =IF(D12="","",IFERROR(VLOOKUP(D12,'produto-entrada-7'!A:M,3,0),"SEM PEDIDO")) | BY12: =IF(D12="","",VLOOKUP(D12,'produto-estoque-total-7'!A:AB,25,0)) | BZ12: =IF(D12="","",IFERROR(VLOOKUP(D12,'produto-estoque-total-7'!A:AB,26,0)/100,0)) | CA12: =IF(D12="","",IFERROR(VLOOKUP(D12,'produto-estoque-total-7'!A:AB,27,0)/100,0)) | CB12: =IF(D12="","",V12*AF12) | CC12: =IF(D12="","",V12*AI12) | CD12: =IF(D12="","",VLOOKUP(D12,'produto-estoque-total-7'!A:AB,28,0))
